Workbook

Sheet Overzicht
A1: Competitor Research – Google-dropshipping
A2: Laatst bijgewerkt: 29-09-2026 · bron bezoekers: SimilarWeb (schatting per maand)
A4: Instellingen (gele cellen mag je aanpassen)
A5: Drempel prioriteit (bezoekers/mnd) | D5: 75000
A6: Drempel monitoren (bezoekers/mnd) | D6: 25000
A7: Minimale match-score (lager = referentie) | D7: 3
A10: Land | B10: Naam | C10: Stores totaal | D10: Prioriteit (≥ drempel) | E10: Monitoren | F10: Onder drempel / geen cijfer | G10: Referentie | H10: Bezoekers prioriteit (som) | I10: Grootste competitor (bezoekers) | J10: Nog niet gekopieerd (prioriteit)
A11: DE | B11: Duitsland | C11: =COUNTIFS('Alle competitors'!$A$5:$A$62,A11) -> 36 | D11: =COUNTIFS('Alle competitors'!$A$5:$A$62,A11,'Alle competitors'!$F$5:$F$62,"Prioriteit") -> 11 | E11: =COUNTIFS('Alle competitors'!$A$5:$A$62,A11,'Alle competitors'!$F$5:$F$62,"Monitoren") -> 4 | F11: =COUNTIFS('Alle competitors'!$A$5:$A$62,A11,'Alle competitors'!$F$5:$F$62,"Onder drempel")+COUNTIFS('Alle competitors'!$A$5:$A$62,A11,'Alle competitors'!$F$5:$F$62,"Geen SW-cijfer") -> 21 | G11: =COUNTIFS('Alle competitors'!$A$5:$A$62,A11,'Alle competitors'!$F$5:$F$62,"Referentie") -> 0 | H11: =SUMIFS('Alle competitors'!$E$5:$E$62,'Alle competitors'!$A$5:$A$62,A11,'Alle competitors'!$F$5:$F$62,"Prioriteit") -> 4076000 | I11: =_xlfn.MAXIFS('Alle competitors'!$E$5:$E$62,'Alle competitors'!$A$5:$A$62,A11,'Alle competitors'!$F$5:$F$62,"<>Referentie") -> 1500000 | J11: =COUNTIFS('Alle competitors'!$A$5:$A$62,A11,'Alle competitors'!$F$5:$F$62,"Prioriteit",'Alle competitors'!$O$5:$O$62,"nee") -> 11
A12: FR | B12: Frankrijk | C12: =COUNTIFS('Alle competitors'!$A$5:$A$62,A12) -> 15 | D12: =COUNTIFS('Alle competitors'!$A$5:$A$62,A12,'Alle competitors'!$F$5:$F$62,"Prioriteit") -> 8 | E12: =COUNTIFS('Alle competitors'!$A$5:$A$62,A12,'Alle competitors'!$F$5:$F$62,"Monitoren") -> 4 | F12: =COUNTIFS('Alle competitors'!$A$5:$A$62,A12,'Alle competitors'!$F$5:$F$62,"Onder drempel")+COUNTIFS('Alle competitors'!$A$5:$A$62,A12,'Alle competitors'!$F$5:$F$62,"Geen SW-cijfer") -> 2 | G12: =COUNTIFS('Alle competitors'!$A$5:$A$62,A12,'Alle competitors'!$F$5:$F$62,"Referentie") -> 1 | H12: =SUMIFS('Alle competitors'!$E$5:$E$62,'Alle competitors'!$A$5:$A$62,A12,'Alle competitors'!$F$5:$F$62,"Prioriteit") -> 1739800 | I12: =_xlfn.MAXIFS('Alle competitors'!$E$5:$E$62,'Alle competitors'!$A$5:$A$62,A12,'Alle competitors'!$F$5:$F$62,"<>Referentie") -> 426400 | J12: =COUNTIFS('Alle competitors'!$A$5:$A$62,A12,'Alle competitors'!$F$5:$F$62,"Prioriteit",'Alle competitors'!$O$5:$O$62,"nee") -> 8
A13: UK | B13: Verenigd Koninkrijk | C13: =COUNTIFS('Alle competitors'!$A$5:$A$62,A13) -> 7 | D13: =COUNTIFS('Alle competitors'!$A$5:$A$62,A13,'Alle competitors'!$F$5:$F$62,"Prioriteit") -> 2 | E13: =COUNTIFS('Alle competitors'!$A$5:$A$62,A13,'Alle competitors'!$F$5:$F$62,"Monitoren") -> 0 | F13: =COUNTIFS('Alle competitors'!$A$5:$A$62,A13,'Alle competitors'!$F$5:$F$62,"Onder drempel")+COUNTIFS('Alle competitors'!$A$5:$A$62,A13,'Alle competitors'!$F$5:$F$62,"Geen SW-cijfer") -> 3 | G13: =COUNTIFS('Alle competitors'!$A$5:$A$62,A13,'Alle competitors'!$F$5:$F$62,"Referentie") -> 2 | H13: =SUMIFS('Alle competitors'!$E$5:$E$62,'Alle competitors'!$A$5:$A$62,A13,'Alle competitors'!$F$5:$F$62,"Prioriteit") -> 287400 | I13: =_xlfn.MAXIFS('Alle competitors'!$E$5:$E$62,'Alle competitors'!$A$5:$A$62,A13,'Alle competitors'!$F$5:$F$62,"<>Referentie") -> 200500 | J13: =COUNTIFS('Alle competitors'!$A$5:$A$62,A13,'Alle competitors'!$F$5:$F$62,"Prioriteit",'Alle competitors'!$O$5:$O$62,"nee") -> 2
A14: Totaal | C14: =SUM(C11:C13) -> 58 | D14: =SUM(D11:D13) -> 21 | E14: =SUM(E11:E13) -> 8 | F14: =SUM(F11:F13) -> 26 | G14: =SUM(G11:G13) -> 3 | H14: =SUM(H11:H13) -> 6103200 | I14: =MAX(I11:I13) -> 1500000 | J14: =SUM(J11:J13) -> 21
A16: Klik op een landcode om naar dat tabblad te gaan.

Sheet Alle competitors
A1: Alle competitors
A2: 58 stores · gesorteerd op land en bezoekers
A4: Land | B4: Store | C4: Website | D4: Categorie | E4: Bezoekers / mnd | F4: Status | G4: Trend vorige mnd | H4: Match-score (1-5) | I4: Paid search | J4: Top landen | K4: Netwerk / operator | L4: Gevonden via | M4: Eerst gevonden | N4: Laatst gecheckt | O4: Producten gekopieerd | P4: Notities
A5: DE | B5: Drune | C5: drune.de | D5: Dames & heren (2000+ producten) | E5: 1500000 | F5: =IF(AND(H5<>"",H5<Overzicht!$D$7),"Referentie",IF(E5="","Geen SW-cijfer",IF(E5>=Overzicht!$D$5,"Prioriteit",IF(E5>=Overzicht!$D$6,"Monitoren","Onder drempel")))) -> Prioriteit | G5: 2.09 | H5: 4 | I5: 0.95 | J5: DE 85%, AT 13% | L5: Tranco-scan | M5: 46292 | N5: 46292 | O5: nee | P5: Grootste vondst. Producttypes verraden bronstores: 'stuttgart-mode', 'vardi dante', 'kaufmann mode', 'holda königsallee'
A6: DE | B6: Karlson Berlin | C6: karlson-berlin.com | D6: Dames & heren, 'Naam | product'-titels | E6: 981100 | F6: =IF(AND(H6<>"",H6<Overzicht!$D$7),"Referentie",IF(E6="","Geen SW-cijfer",IF(E6>=Overzicht!$D$5,"Prioriteit",IF(E6>=Overzicht!$D$6,"Monitoren","Onder drempel")))) -> Prioriteit | G6: 1.81 | H6: 5 | I6: 0.4 | J6: DE 100% | L6: Zoekopdracht + Tranco | M6: 46292 | N6: 46292 | O6: nee | P6: Symmetry-thema, 100% prijzen op ,95
A7: DE | B7: Nordheim Mode | C7: nordheim-mode.de | D7: Dames & heren, schoenen, bikini's | E7: 545500 | F7: =IF(AND(H7<>"",H7<Overzicht!$D$7),"Referentie",IF(E7="","Geen SW-cijfer",IF(E7>=Overzicht!$D$5,"Prioriteit",IF(E7>=Overzicht!$D$6,"Monitoren","Onder drempel")))) -> Prioriteit | G7: -0.05 | H7: 5 | I7: 0.87 | J7: DE 90%, IT 4%, PT 4% | L7: Tranco-scan | M7: 46292 | N7: 46292 | O7: nee | P7: Impulse-thema (zoals Daily Berlin), 12 taalmarkten
A8: DE | B8: Leon Boutique | C8: leonboutique.co | D8: Dames & heren, 'Naam | product' | E8: 242600 | F8: =IF(AND(H8<>"",H8<Overzicht!$D$7),"Referentie",IF(E8="","Geen SW-cijfer",IF(E8>=Overzicht!$D$5,"Prioriteit",IF(E8>=Overzicht!$D$6,"Monitoren","Onder drempel")))) -> Prioriteit | G8: -0.2 | H8: 5 | I8: 0.78 | J8: DE 56%, PK 37%, NL 3% | L8: Tranco-scan (FR-lijst) | M8: 46292 | N8: 46292 | O8: nee | P8: Gevonden tijdens FR-ronde; DE 56%, PK 37%
A9: DE | B9: Lozenda Fashion | C9: lozendafashion.com | D9: Dames & heren, 2000+ producten | E9: 192100 | F9: =IF(AND(H9<>"",H9<Overzicht!$D$7),"Referentie",IF(E9="","Geen SW-cijfer",IF(E9>=Overzicht!$D$5,"Prioriteit",IF(E9>=Overzicht!$D$6,"Monitoren","Onder drempel")))) -> Prioriteit | G9: -0.26 | H9: 5 | I9: 0.82 | J9: DE 44%, IT 10%, FR 10% | L9: Tranco-scan | M9: 46292 | N9: 46292 | O9: nee | P9: Actief in DE/IT/FR, 12 markten
A10: DE | B10: Sassy Classy | C10: sassyclassy.de | D10: Dames, blouses/musselin | E10: 148600 | F10: =IF(AND(H10<>"",H10<Overzicht!$D$7),"Referentie",IF(E10="","Geen SW-cijfer",IF(E10>=Overzicht!$D$5,"Prioriteit",IF(E10>=Overzicht!$D$6,"Monitoren","Onder drempel")))) -> Prioriteit | G10: 0.16 | H10: 3 | I10: 0.29 | J10: DE 99% | L10: Tranco-scan | M10: 46292 | N10: 46292 | O10: nee | P10: Oogt meer als eigen boutique-label; vooral organisch verkeer
A11: DE | B11: Risora | C11: risora-shop.de | D11: Gemengd: mode + huis/tuin | E11: 121300 | F11: =IF(AND(H11<>"",H11<Overzicht!$D$7),"Referentie",IF(E11="","Geen SW-cijfer",IF(E11>=Overzicht!$D$5,"Prioriteit",IF(E11>=Overzicht!$D$6,"Monitoren","Onder drempel")))) -> Prioriteit | G11: 0.06 | H11: 4 | I11: 0.88 | J11: DE 82%, CH 11%, US 7% | L11: Tranco-scan | M11: 46292 | N11: 46292 | O11: nee | P11: Themanaam letterlijk 'Risora - Google'
A12: DE | B12: Velareeh Haus | C12: velareehhaus.com | D12: Dames & heren, jurken | E12: 95300 | F12: =IF(AND(H12<>"",H12<Overzicht!$D$7),"Referentie",IF(E12="","Geen SW-cijfer",IF(E12>=Overzicht!$D$5,"Prioriteit",IF(E12>=Overzicht!$D$6,"Monitoren","Onder drempel")))) -> Prioriteit | G12: 0.47 | H12: 5 | I12: 0.77 | J12: DE 78%, NL 22% | L12: Tranco-scan | M12: 46292 | N12: 46292 | O12: nee | P12: Thema 'Kopie van ...' → vermoedelijk NL-operator; DE+NL verkeer
A13: DE | B13: Nordspur | C13: nordspur.de | D13: Jassen/steppjassen D&H | E13: 89000 | F13: =IF(AND(H13<>"",H13<Overzicht!$D$7),"Referentie",IF(E13="","Geen SW-cijfer",IF(E13>=Overzicht!$D$5,"Prioriteit",IF(E13>=Overzicht!$D$6,"Monitoren","Onder drempel")))) -> Prioriteit | G13: 0.2 | H13: 5 | I13: 0.87 | J13: DE 98% | L13: Tranco-scan | M13: 46292 | N13: 46292 | O13: nee | P13: Impact-thema, 100% ,95
A14: DE | B14: Falkenberg Mode | C14: falkenberg-mode.de | D14: Dames & heren, badmode, jurken | E14: 83600 | F14: =IF(AND(H14<>"",H14<Overzicht!$D$7),"Referentie",IF(E14="","Geen SW-cijfer",IF(E14>=Overzicht!$D$5,"Prioriteit",IF(E14>=Overzicht!$D$6,"Monitoren","Onder drempel")))) -> Prioriteit | G14: 0.22 | H14: 5 | I14: 0 | J14: DE 100% | L14: Tranco-scan | M14: 46292 | N14: 46292 | O14: nee | P14: SimilarWeb meldt 100% organisch - controleren
A15: DE | B15: Alpenkind Mode | C15: alpenkindmode.com | D15: Dirndl/tracht + casual D&H | E15: 76900 | F15: =IF(AND(H15<>"",H15<Overzicht!$D$7),"Referentie",IF(E15="","Geen SW-cijfer",IF(E15>=Overzicht!$D$5,"Prioriteit",IF(E15>=Overzicht!$D$6,"Monitoren","Onder drempel")))) -> Prioriteit | G15: -0.33 | H15: 5 | I15: 0.8 | J15: DE 92%, AT 8% | L15: Zoekopdracht + Tranco | M15: 46292 | N15: 46292 | O15: nee | P15: Net boven 75K, dalend
A16: DE | B16: Ladypolitan | C16: ladypolitan.de | D16: Dames | E16: 67000 | F16: =IF(AND(H16<>"",H16<Overzicht!$D$7),"Referentie",IF(E16="","Geen SW-cijfer",IF(E16>=Overzicht!$D$5,"Prioriteit",IF(E16>=Overzicht!$D$6,"Monitoren","Onder drempel")))) -> Monitoren | G16: -0.27 | H16: 3 | I16: 0.16 | J16: DE 70%, US 16%, AT 9% | L16: Tranco-scan | M16: 46292 | N16: 46292 | O16: nee | P16: Lijkt echte boutique, vooral organisch
A17: DE | B17: Walther Mode | C17: walther-mode.com | D17: Dames & heren | E17: 41500 | F17: =IF(AND(H17<>"",H17<Overzicht!$D$7),"Referentie",IF(E17="","Geen SW-cijfer",IF(E17>=Overzicht!$D$5,"Prioriteit",IF(E17>=Overzicht!$D$6,"Monitoren","Onder drempel")))) -> Monitoren | G17: 5.9 | H17: 5 | I17: 0.83 | J17: IT 47%, US 20%, DE 11% | L17: Zoekopdracht | M17: 46292 | N17: 46292 | O17: nee | P17: Sterk groeiend; 12 taalmarkten, vooral IT-verkeer
A18: DE | B18: Nicole Modehaus | C18: nicole-modehaus.de | D18: Dames & heren | E18: 32400 | F18: =IF(AND(H18<>"",H18<Overzicht!$D$7),"Referentie",IF(E18="","Geen SW-cijfer",IF(E18>=Overzicht!$D$5,"Prioriteit",IF(E18>=Overzicht!$D$6,"Monitoren","Onder drempel")))) -> Monitoren | G18: -0.04 | H18: 5 | K18: Nicole (nina-nicole.de / nicole-modehaus.de) | L18: Tranco-scan | M18: 46292 | N18: 46292 | O18: nee | P18: Zelfde catalogus als nina-nicole.de; 85% paid social
A19: DE | B19: Cecile Lavelle | C19: cecilelavelle.com | D19: Dames & heren, jassen | E19: 26200 | F19: =IF(AND(H19<>"",H19<Overzicht!$D$7),"Referentie",IF(E19="","Geen SW-cijfer",IF(E19>=Overzicht!$D$5,"Prioriteit",IF(E19>=Overzicht!$D$6,"Monitoren","Onder drempel")))) -> Monitoren | G19: -0.6 | H19: 5 | I19: 0.73 | J19: DE 28%, US 26%, UK 22% | L19: Zoekopdracht | M19: 46292 | N19: 46292 | O19: nee | P19: DE/US/UK verkeer
A20: DE | B20: Althausmode | C20: althausmode.com | D20: Mode D&H | F20: =IF(AND(H20<>"",H20<Overzicht!$D$7),"Referentie",IF(E20="","Geen SW-cijfer",IF(E20>=Overzicht!$D$5,"Prioriteit",IF(E20>=Overzicht!$D$6,"Monitoren","Onder drempel")))) -> Geen SW-cijfer | K20: Devjour-netwerk (Althaus/FabrikStil/Leipzig/Schlossberg) | L20: Zoekopdracht/Tranco | M20: 46292 | N20: 46292 | O20: nee | P20: <25K / geen SW-data. niet in SimilarWeb
A21: DE | B21: Annoboutique | C21: annoboutique.com | D21: Mode D&H | F21: =IF(AND(H21<>"",H21<Overzicht!$D$7),"Referentie",IF(E21="","Geen SW-cijfer",IF(E21>=Overzicht!$D$5,"Prioriteit",IF(E21>=Overzicht!$D$6,"Monitoren","Onder drempel")))) -> Geen SW-cijfer | L21: Zoekopdracht/Tranco | M21: 46292 | N21: 46292 | O21: nee | P21: <25K / geen SW-data. geen totaal
A22: DE | B22: Bellarosamode | C22: bellarosamode.com | D22: Mode D&H | F22: =IF(AND(H22<>"",H22<Overzicht!$D$7),"Referentie",IF(E22="","Geen SW-cijfer",IF(E22>=Overzicht!$D$5,"Prioriteit",IF(E22>=Overzicht!$D$6,"Monitoren","Onder drempel")))) -> Geen SW-cijfer | J22: UK 83%, FR 17% | L22: Zoekopdracht/Tranco | M22: 46292 | N22: 46292 | O22: nee | P22: <25K / geen SW-data. geen totaal (UK/FR)
A23: DE | B23: Berlinlook | C23: berlinlook.com | D23: Mode D&H | F23: =IF(AND(H23<>"",H23<Overzicht!$D$7),"Referentie",IF(E23="","Geen SW-cijfer",IF(E23>=Overzicht!$D$5,"Prioriteit",IF(E23>=Overzicht!$D$6,"Monitoren","Onder drempel")))) -> Geen SW-cijfer | J23: DE 93%, SE 7% | L23: Zoekopdracht/Tranco | M23: 46292 | N23: 46292 | O23: nee | P23: <25K / geen SW-data. geen totaal
A24: DE | B24: Berlinsprime | C24: berlinsprime.de | D24: Mode D&H | F24: =IF(AND(H24<>"",H24<Overzicht!$D$7),"Referentie",IF(E24="","Geen SW-cijfer",IF(E24>=Overzicht!$D$5,"Prioriteit",IF(E24>=Overzicht!$D$6,"Monitoren","Onder drempel")))) -> Geen SW-cijfer | L24: Zoekopdracht/Tranco | M24: 46292 | N24: 46292 | O24: nee | P24: <25K / geen SW-data. geen data
A25: DE | B25: Chaps Herrenmode | C25: chaps-herrenmode.de | D25: Mode D&H | F25: =IF(AND(H25<>"",H25<Overzicht!$D$7),"Referentie",IF(E25="","Geen SW-cijfer",IF(E25>=Overzicht!$D$5,"Prioriteit",IF(E25>=Overzicht!$D$6,"Monitoren","Onder drempel")))) -> Geen SW-cijfer | K25: Chaps (chaps-herrenmode.de / chapslondon.co.uk) | L25: Zoekopdracht/Tranco | M25: 46292 | N25: 46292 | O25: nee | P25: <25K / geen SW-data. geen data
A26: DE | B26: Fabrikstil | C26: fabrikstil.de | D26: Mode D&H | F26: =IF(AND(H26<>"",H26<Overzicht!$D$7),"Referentie",IF(E26="","Geen SW-cijfer",IF(E26>=Overzicht!$D$5,"Prioriteit",IF(E26>=Overzicht!$D$6,"Monitoren","Onder drempel")))) -> Geen SW-cijfer | K26: Devjour-netwerk (Althaus/FabrikStil/Leipzig/Schlossberg) | L26: Zoekopdracht/Tranco | M26: 46292 | N26: 46292 | O26: nee | P26: <25K / geen SW-data. niet in SimilarWeb
A27: DE | B27: Falkenhof Mode | C27: falkenhof-mode.de | D27: Mode D&H | F27: =IF(AND(H27<>"",H27<Overzicht!$D$7),"Referentie",IF(E27="","Geen SW-cijfer",IF(E27>=Overzicht!$D$5,"Prioriteit",IF(E27>=Overzicht!$D$6,"Monitoren","Onder drempel")))) -> Geen SW-cijfer | J27: DE 100% | L27: Zoekopdracht/Tranco | M27: 46292 | N27: 46292 | O27: nee | P27: <25K / geen SW-data. geen totaal (94% paid)
A28: DE | B28: Herrmann Modehaus | C28: herrmann-modehaus.de | D28: Mode D&H | F28: =IF(AND(H28<>"",H28<Overzicht!$D$7),"Referentie",IF(E28="","Geen SW-cijfer",IF(E28>=Overzicht!$D$5,"Prioriteit",IF(E28>=Overzicht!$D$6,"Monitoren","Onder drempel")))) -> Geen SW-cijfer | L28: Zoekopdracht/Tranco | M28: 46292 | N28: 46292 | O28: nee | P28: <25K / geen SW-data. geen totaal
A29: DE | B29: Kaufmannmode | C29: kaufmannmode.de | D29: Mode D&H | F29: =IF(AND(H29<>"",H29<Overzicht!$D$7),"Referentie",IF(E29="","Geen SW-cijfer",IF(E29>=Overzicht!$D$5,"Prioriteit",IF(E29>=Overzicht!$D$6,"Monitoren","Onder drempel")))) -> Geen SW-cijfer | K29: Bronstore van Drune | L29: Zoekopdracht/Tranco | M29: 46292 | N29: 46292 | O29: nee | P29: <25K / geen SW-data. geen data; bronstore van Drune
A30: DE | B30: Kiezstudio | C30: kiezstudio.com | D30: Mode D&H | F30: =IF(AND(H30<>"",H30<Overzicht!$D$7),"Referentie",IF(E30="","Geen SW-cijfer",IF(E30>=Overzicht!$D$5,"Prioriteit",IF(E30>=Overzicht!$D$6,"Monitoren","Onder drempel")))) -> Geen SW-cijfer | L30: Zoekopdracht/Tranco | M30: 46292 | N30: 46292 | O30: nee | P30: <25K / geen SW-data. geen data
A31: DE | B31: Leipzigmodehausshop | C31: leipzigmodehausshop.de | D31: Mode D&H | F31: =IF(AND(H31<>"",H31<Overzicht!$D$7),"Referentie",IF(E31="","Geen SW-cijfer",IF(E31>=Overzicht!$D$5,"Prioriteit",IF(E31>=Overzicht!$D$6,"Monitoren","Onder drempel")))) -> Geen SW-cijfer | K31: Devjour-netwerk (Althaus/FabrikStil/Leipzig/Schlossberg) | L31: Zoekopdracht/Tranco | M31: 46292 | N31: 46292 | O31: nee | P31: <25K / geen SW-data. geen data
A32: DE | B32: Mathilde Munchen | C32: mathilde-munchen.de | D32: Mode D&H | F32: =IF(AND(H32<>"",H32<Overzicht!$D$7),"Referentie",IF(E32="","Geen SW-cijfer",IF(E32>=Overzicht!$D$5,"Prioriteit",IF(E32>=Overzicht!$D$6,"Monitoren","Onder drempel")))) -> Geen SW-cijfer | J32: PT 64%, DE 36% | L32: Zoekopdracht/Tranco | M32: 46292 | N32: 46292 | O32: nee | P32: <25K / geen SW-data. geen totaal
A33: DE | B33: Modehaushartmann | C33: modehaushartmann.de | D33: Mode D&H | F33: =IF(AND(H33<>"",H33<Overzicht!$D$7),"Referentie",IF(E33="","Geen SW-cijfer",IF(E33>=Overzicht!$D$5,"Prioriteit",IF(E33>=Overzicht!$D$6,"Monitoren","Onder drempel")))) -> Geen SW-cijfer | J33: DE 98% | L33: Zoekopdracht/Tranco | M33: 46292 | N33: 46292 | O33: nee | P33: <25K / geen SW-data. geen totaal (92% paid)
A34: DE | B34: Modemuller | C34: modemuller.de | D34: Mode D&H | F34: =IF(AND(H34<>"",H34<Overzicht!$D$7),"Referentie",IF(E34="","Geen SW-cijfer",IF(E34>=Overzicht!$D$5,"Prioriteit",IF(E34>=Overzicht!$D$6,"Monitoren","Onder drempel")))) -> Geen SW-cijfer | L34: Zoekopdracht/Tranco | M34: 46292 | N34: 46292 | O34: nee | P34: <25K / geen SW-data. geen data
A35: DE | B35: Nina Nicole | C35: nina-nicole.de | D35: Mode D&H | F35: =IF(AND(H35<>"",H35<Overzicht!$D$7),"Referentie",IF(E35="","Geen SW-cijfer",IF(E35>=Overzicht!$D$5,"Prioriteit",IF(E35>=Overzicht!$D$6,"Monitoren","Onder drempel")))) -> Geen SW-cijfer | K35: Nicole (nina-nicole.de / nicole-modehaus.de) | L35: Zoekopdracht/Tranco | M35: 46292 | N35: 46292 | O35: nee | P35: <25K / geen SW-data. geen data; zusterstore van nicole-modehaus.de
A36: DE | B36: Nordmodehaus | C36: nordmodehaus.com | D36: Mode D&H | F36: =IF(AND(H36<>"",H36<Overzicht!$D$7),"Referentie",IF(E36="","Geen SW-cijfer",IF(E36>=Overzicht!$D$5,"Prioriteit",IF(E36>=Overzicht!$D$6,"Monitoren","Onder drempel")))) -> Geen SW-cijfer | J36: DE 97% | L36: Zoekopdracht/Tranco | M36: 46292 | N36: 46292 | O36: nee | P36: <25K / geen SW-data. geen totaal (+255%, 96% paid) → volgende maand checken
A37: DE | B37: Orthoday | C37: orthoday.de | D37: Mode D&H | F37: =IF(AND(H37<>"",H37<Overzicht!$D$7),"Referentie",IF(E37="","Geen SW-cijfer",IF(E37>=Overzicht!$D$5,"Prioriteit",IF(E37>=Overzicht!$D$6,"Monitoren","Onder drempel")))) -> Geen SW-cijfer | L37: Zoekopdracht/Tranco | M37: 46292 | N37: 46292 | O37: nee | P37: <25K / geen SW-data. geen totaal
A38: DE | B38: Sophia Zurich | C38: sophia-zurich.com | D38: Mode D&H | F38: =IF(AND(H38<>"",H38<Overzicht!$D$7),"Referentie",IF(E38="","Geen SW-cijfer",IF(E38>=Overzicht!$D$5,"Prioriteit",IF(E38>=Overzicht!$D$6,"Monitoren","Onder drempel")))) -> Geen SW-cijfer | J38: CH 70%, DE 30% | L38: Zoekopdracht/Tranco | M38: 46292 | N38: 46292 | O38: nee | P38: <25K / geen SW-data. geen totaal (CH)
A39: DE | B39: Stefanberlin | C39: stefanberlin.com | D39: Mode D&H | F39: =IF(AND(H39<>"",H39<Overzicht!$D$7),"Referentie",IF(E39="","Geen SW-cijfer",IF(E39>=Overzicht!$D$5,"Prioriteit",IF(E39>=Overzicht!$D$6,"Monitoren","Onder drempel")))) -> Geen SW-cijfer | J39: DE 100% | L39: Zoekopdracht/Tranco | M39: 46292 | N39: 46292 | O39: nee | P39: <25K / geen SW-data. geen totaal (+338%)
A40: DE | B40: Wittenwald | C40: wittenwald.de | D40: Mode D&H | F40: =IF(AND(H40<>"",H40<Overzicht!$D$7),"Referentie",IF(E40="","Geen SW-cijfer",IF(E40>=Overzicht!$D$5,"Prioriteit",IF(E40>=Overzicht!$D$6,"Monitoren","Onder drempel")))) -> Geen SW-cijfer | J40: ES 55%, AT 30%, DE 15% | L40: Zoekopdracht/Tranco | M40: 46292 | N40: 46292 | O40: nee | P40: <25K / geen SW-data. geen totaal (groei +125%, vooral ES/AT)
A41: FR | B41: Moreau Lyon | C41: moreau-lyon.fr | D41: Dames & heren | E41: 426400 | F41: =IF(AND(H41<>"",H41<Overzicht!$D$7),"Referentie",IF(E41="","Geen SW-cijfer",IF(E41>=Overzicht!$D$5,"Prioriteit",IF(E41>=Overzicht!$D$6,"Monitoren","Onder drempel")))) -> Prioriteit | G41: 0.3 | H41: 5 | I41: 0.69 | J41: FR 98% | L41: Tranco-scan | M41: 46292 | N41: 46292 | O41: nee | P41: Sleek-thema, 100% ,95, 'MERK | PRODUCT'-titels
...

Sheet DE
A1: DE
A2: Duitsland · 36 stores
A4: Land | B4: Store | C4: Website | D4: Categorie | E4: Bezoekers / mnd | F4: Status | G4: Trend vorige mnd | H4: Match-score (1-5) | I4: Paid search | J4: Top landen | K4: Netwerk / operator | L4: Gevonden via | M4: Eerst gevonden | N4: Laatst gecheckt | O4: Producten gekopieerd | P4: Notities
A5: DE | B5: Drune | C5: drune.de | D5: Dames & heren (2000+ producten) | E5: 1500000 | F5: =IF(AND(H5<>"",H5<Overzicht!$D$7),"Referentie",IF(E5="","Geen SW-cijfer",IF(E5>=Overzicht!$D$5,"Prioriteit",IF(E5>=Overzicht!$D$6,"Monitoren","Onder drempel")))) -> Prioriteit | G5: 2.09 | H5: 4 | I5: 0.95 | J5: DE 85%, AT 13% | L5: Tranco-scan | M5: 46292 | N5: 46292 | O5: nee | P5: Grootste vondst. Producttypes verraden bronstores: 'stuttgart-mode', 'vardi dante', 'kaufmann mode', 'holda königsallee'
A6: DE | B6: Karlson Berlin | C6: karlson-berlin.com | D6: Dames & heren, 'Naam | product'-titels | E6: 981100 | F6: =IF(AND(H6<>"",H6<Overzicht!$D$7),"Referentie",IF(E6="","Geen SW-cijfer",IF(E6>=Overzicht!$D$5,"Prioriteit",IF(E6>=Overzicht!$D$6,"Monitoren","Onder drempel")))) -> Prioriteit | G6: 1.81 | H6: 5 | I6: 0.4 | J6: DE 100% | L6: Zoekopdracht + Tranco | M6: 46292 | N6: 46292 | O6: nee | P6: Symmetry-thema, 100% prijzen op ,95
A7: DE | B7: Nordheim Mode | C7: nordheim-mode.de | D7: Dames & heren, schoenen, bikini's | E7: 545500 | F7: =IF(AND(H7<>"",H7<Overzicht!$D$7),"Referentie",IF(E7="","Geen SW-cijfer",IF(E7>=Overzicht!$D$5,"Prioriteit",IF(E7>=Overzicht!$D$6,"Monitoren","Onder drempel")))) -> Prioriteit | G7: -0.05 | H7: 5 | I7: 0.87 | J7: DE 90%, IT 4%, PT 4% | L7: Tranco-scan | M7: 46292 | N7: 46292 | O7: nee | P7: Impulse-thema (zoals Daily Berlin), 12 taalmarkten
A8: DE | B8: Leon Boutique | C8: leonboutique.co | D8: Dames & heren, 'Naam | product' | E8: 242600 | F8: =IF(AND(H8<>"",H8<Overzicht!$D$7),"Referentie",IF(E8="","Geen SW-cijfer",IF(E8>=Overzicht!$D$5,"Prioriteit",IF(E8>=Overzicht!$D$6,"Monitoren","Onder drempel")))) -> Prioriteit | G8: -0.2 | H8: 5 | I8: 0.78 | J8: DE 56%, PK 37%, NL 3% | L8: Tranco-scan (FR-lijst) | M8: 46292 | N8: 46292 | O8: nee | P8: Gevonden tijdens FR-ronde; DE 56%, PK 37%
A9: DE | B9: Lozenda Fashion | C9: lozendafashion.com | D9: Dames & heren, 2000+ producten | E9: 192100 | F9: =IF(AND(H9<>"",H9<Overzicht!$D$7),"Referentie",IF(E9="","Geen SW-cijfer",IF(E9>=Overzicht!$D$5,"Prioriteit",IF(E9>=Overzicht!$D$6,"Monitoren","Onder drempel")))) -> Prioriteit | G9: -0.26 | H9: 5 | I9: 0.82 | J9: DE 44%, IT 10%, FR 10% | L9: Tranco-scan | M9: 46292 | N9: 46292 | O9: nee | P9: Actief in DE/IT/FR, 12 markten
A10: DE | B10: Sassy Classy | C10: sassyclassy.de | D10: Dames, blouses/musselin | E10: 148600 | F10: =IF(AND(H10<>"",H10<Overzicht!$D$7),"Referentie",IF(E10="","Geen SW-cijfer",IF(E10>=Overzicht!$D$5,"Prioriteit",IF(E10>=Overzicht!$D$6,"Monitoren","Onder drempel")))) -> Prioriteit | G10: 0.16 | H10: 3 | I10: 0.29 | J10: DE 99% | L10: Tranco-scan | M10: 46292 | N10: 46292 | O10: nee | P10: Oogt meer als eigen boutique-label; vooral organisch verkeer
A11: DE | B11: Risora | C11: risora-shop.de | D11: Gemengd: mode + huis/tuin | E11: 121300 | F11: =IF(AND(H11<>"",H11<Overzicht!$D$7),"Referentie",IF(E11="","Geen SW-cijfer",IF(E11>=Overzicht!$D$5,"Prioriteit",IF(E11>=Overzicht!$D$6,"Monitoren","Onder drempel")))) -> Prioriteit | G11: 0.06 | H11: 4 | I11: 0.88 | J11: DE 82%, CH 11%, US 7% | L11: Tranco-scan | M11: 46292 | N11: 46292 | O11: nee | P11: Themanaam letterlijk 'Risora - Google'
A12: DE | B12: Velareeh Haus | C12: velareehhaus.com | D12: Dames & heren, jurken | E12: 95300 | F12: =IF(AND(H12<>"",H12<Overzicht!$D$7),"Referentie",IF(E12="","Geen SW-cijfer",IF(E12>=Overzicht!$D$5,"Prioriteit",IF(E12>=Overzicht!$D$6,"Monitoren","Onder drempel")))) -> Prioriteit | G12: 0.47 | H12: 5 | I12: 0.77 | J12: DE 78%, NL 22% | L12: Tranco-scan | M12: 46292 | N12: 46292 | O12: nee | P12: Thema 'Kopie van ...' → vermoedelijk NL-operator; DE+NL verkeer
A13: DE | B13: Nordspur | C13: nordspur.de | D13: Jassen/steppjassen D&H | E13: 89000 | F13: =IF(AND(H13<>"",H13<Overzicht!$D$7),"Referentie",IF(E13="","Geen SW-cijfer",IF(E13>=Overzicht!$D$5,"Prioriteit",IF(E13>=Overzicht!$D$6,"Monitoren","Onder drempel")))) -> Prioriteit | G13: 0.2 | H13: 5 | I13: 0.87 | J13: DE 98% | L13: Tranco-scan | M13: 46292 | N13: 46292 | O13: nee | P13: Impact-thema, 100% ,95
A14: DE | B14: Falkenberg Mode | C14: falkenberg-mode.de | D14: Dames & heren, badmode, jurken | E14: 83600 | F14: =IF(AND(H14<>"",H14<Overzicht!$D$7),"Referentie",IF(E14="","Geen SW-cijfer",IF(E14>=Overzicht!$D$5,"Prioriteit",IF(E14>=Overzicht!$D$6,"Monitoren","Onder drempel")))) -> Prioriteit | G14: 0.22 | H14: 5 | I14: 0 | J14: DE 100% | L14: Tranco-scan | M14: 46292 | N14: 46292 | O14: nee | P14: SimilarWeb meldt 100% organisch - controleren
A15: DE | B15: Alpenkind Mode | C15: alpenkindmode.com | D15: Dirndl/tracht + casual D&H | E15: 76900 | F15: =IF(AND(H15<>"",H15<Overzicht!$D$7),"Referentie",IF(E15="","Geen SW-cijfer",IF(E15>=Overzicht!$D$5,"Prioriteit",IF(E15>=Overzicht!$D$6,"Monitoren","Onder drempel")))) -> Prioriteit | G15: -0.33 | H15: 5 | I15: 0.8 | J15: DE 92%, AT 8% | L15: Zoekopdracht + Tranco | M15: 46292 | N15: 46292 | O15: nee | P15: Net boven 75K, dalend
A16: DE | B16: Ladypolitan | C16: ladypolitan.de | D16: Dames | E16: 67000 | F16: =IF(AND(H16<>"",H16<Overzicht!$D$7),"Referentie",IF(E16="","Geen SW-cijfer",IF(E16>=Overzicht!$D$5,"Prioriteit",IF(E16>=Overzicht!$D$6,"Monitoren","Onder drempel")))) -> Monitoren | G16: -0.27 | H16: 3 | I16: 0.16 | J16: DE 70%, US 16%, AT 9% | L16: Tranco-scan | M16: 46292 | N16: 46292 | O16: nee | P16: Lijkt echte boutique, vooral organisch
A17: DE | B17: Walther Mode | C17: walther-mode.com | D17: Dames & heren | E17: 41500 | F17: =IF(AND(H17<>"",H17<Overzicht!$D$7),"Referentie",IF(E17="","Geen SW-cijfer",IF(E17>=Overzicht!$D$5,"Prioriteit",IF(E17>=Overzicht!$D$6,"Monitoren","Onder drempel")))) -> Monitoren | G17: 5.9 | H17: 5 | I17: 0.83 | J17: IT 47%, US 20%, DE 11% | L17: Zoekopdracht | M17: 46292 | N17: 46292 | O17: nee | P17: Sterk groeiend; 12 taalmarkten, vooral IT-verkeer
A18: DE | B18: Nicole Modehaus | C18: nicole-modehaus.de | D18: Dames & heren | E18: 32400 | F18: =IF(AND(H18<>"",H18<Overzicht!$D$7),"Referentie",IF(E18="","Geen SW-cijfer",IF(E18>=Overzicht!$D$5,"Prioriteit",IF(E18>=Overzicht!$D$6,"Monitoren","Onder drempel")))) -> Monitoren | G18: -0.04 | H18: 5 | K18: Nicole (nina-nicole.de / nicole-modehaus.de) | L18: Tranco-scan | M18: 46292 | N18: 46292 | O18: nee | P18: Zelfde catalogus als nina-nicole.de; 85% paid social
A19: DE | B19: Cecile Lavelle | C19: cecilelavelle.com | D19: Dames & heren, jassen | E19: 26200 | F19: =IF(AND(H19<>"",H19<Overzicht!$D$7),"Referentie",IF(E19="","Geen SW-cijfer",IF(E19>=Overzicht!$D$5,"Prioriteit",IF(E19>=Overzicht!$D$6,"Monitoren","Onder drempel")))) -> Monitoren | G19: -0.6 | H19: 5 | I19: 0.73 | J19: DE 28%, US 26%, UK 22% | L19: Zoekopdracht | M19: 46292 | N19: 46292 | O19: nee | P19: DE/US/UK verkeer
A20: DE | B20: Althausmode | C20: althausmode.com | D20: Mode D&H | F20: =IF(AND(H20<>"",H20<Overzicht!$D$7),"Referentie",IF(E20="","Geen SW-cijfer",IF(E20>=Overzicht!$D$5,"Prioriteit",IF(E20>=Overzicht!$D$6,"Monitoren","Onder drempel")))) -> Geen SW-cijfer | K20: Devjour-netwerk (Althaus/FabrikStil/Leipzig/Schlossberg) | L20: Zoekopdracht/Tranco | M20: 46292 | N20: 46292 | O20: nee | P20: <25K / geen SW-data. niet in SimilarWeb
A21: DE | B21: Annoboutique | C21: annoboutique.com | D21: Mode D&H | F21: =IF(AND(H21<>"",H21<Overzicht!$D$7),"Referentie",IF(E21="","Geen SW-cijfer",IF(E21>=Overzicht!$D$5,"Prioriteit",IF(E21>=Overzicht!$D$6,"Monitoren","Onder drempel")))) -> Geen SW-cijfer | L21: Zoekopdracht/Tranco | M21: 46292 | N21: 46292 | O21: nee | P21: <25K / geen SW-data. geen totaal
A22: DE | B22: Bellarosamode | C22: bellarosamode.com | D22: Mode D&H | F22: =IF(AND(H22<>"",H22<Overzicht!$D$7),"Referentie",IF(E22="","Geen SW-cijfer",IF(E22>=Overzicht!$D$5,"Prioriteit",IF(E22>=Overzicht!$D$6,"Monitoren","Onder drempel")))) -> Geen SW-cijfer | J22: UK 83%, FR 17% | L22: Zoekopdracht/Tranco | M22: 46292 | N22: 46292 | O22: nee | P22: <25K / geen SW-data. geen totaal (UK/FR)
A23: DE | B23: Berlinlook | C23: berlinlook.com | D23: Mode D&H | F23: =IF(AND(H23<>"",H23<Overzicht!$D$7),"Referentie",IF(E23="","Geen SW-cijfer",IF(E23>=Overzicht!$D$5,"Prioriteit",IF(E23>=Overzicht!$D$6,"Monitoren","Onder drempel")))) -> Geen SW-cijfer | J23: DE 93%, SE 7% | L23: Zoekopdracht/Tranco | M23: 46292 | N23: 46292 | O23: nee | P23: <25K / geen SW-data. geen totaal
A24: DE | B24: Berlinsprime | C24: berlinsprime.de | D24: Mode D&H | F24: =IF(AND(H24<>"",H24<Overzicht!$D$7),"Referentie",IF(E24="","Geen SW-cijfer",IF(E24>=Overzicht!$D$5,"Prioriteit",IF(E24>=Overzicht!$D$6,"Monitoren","Onder drempel")))) -> Geen SW-cijfer | L24: Zoekopdracht/Tranco | M24: 46292 | N24: 46292 | O24: nee | P24: <25K / geen SW-data. geen data
A25: DE | B25: Chaps Herrenmode | C25: chaps-herrenmode.de | D25: Mode D&H | F25: =IF(AND(H25<>"",H25<Overzicht!$D$7),"Referentie",IF(E25="","Geen SW-cijfer",IF(E25>=Overzicht!$D$5,"Prioriteit",IF(E25>=Overzicht!$D$6,"Monitoren","Onder drempel")))) -> Geen SW-cijfer | K25: Chaps (chaps-herrenmode.de / chapslondon.co.uk) | L25: Zoekopdracht/Tranco | M25: 46292 | N25: 46292 | O25: nee | P25: <25K / geen SW-data. geen data
A26: DE | B26: Fabrikstil | C26: fabrikstil.de | D26: Mode D&H | F26: =IF(AND(H26<>"",H26<Overzicht!$D$7),"Referentie",IF(E26="","Geen SW-cijfer",IF(E26>=Overzicht!$D$5,"Prioriteit",IF(E26>=Overzicht!$D$6,"Monitoren","Onder drempel")))) -> Geen SW-cijfer | K26: Devjour-netwerk (Althaus/FabrikStil/Leipzig/Schlossberg) | L26: Zoekopdracht/Tranco | M26: 46292 | N26: 46292 | O26: nee | P26: <25K / geen SW-data. niet in SimilarWeb
A27: DE | B27: Falkenhof Mode | C27: falkenhof-mode.de | D27: Mode D&H | F27: =IF(AND(H27<>"",H27<Overzicht!$D$7),"Referentie",IF(E27="","Geen SW-cijfer",IF(E27>=Overzicht!$D$5,"Prioriteit",IF(E27>=Overzicht!$D$6,"Monitoren","Onder drempel")))) -> Geen SW-cijfer | J27: DE 100% | L27: Zoekopdracht/Tranco | M27: 46292 | N27: 46292 | O27: nee | P27: <25K / geen SW-data. geen totaal (94% paid)
A28: DE | B28: Herrmann Modehaus | C28: herrmann-modehaus.de | D28: Mode D&H | F28: =IF(AND(H28<>"",H28<Overzicht!$D$7),"Referentie",IF(E28="","Geen SW-cijfer",IF(E28>=Overzicht!$D$5,"Prioriteit",IF(E28>=Overzicht!$D$6,"Monitoren","Onder drempel")))) -> Geen SW-cijfer | L28: Zoekopdracht/Tranco | M28: 46292 | N28: 46292 | O28: nee | P28: <25K / geen SW-data. geen totaal
A29: DE | B29: Kaufmannmode | C29: kaufmannmode.de | D29: Mode D&H | F29: =IF(AND(H29<>"",H29<Overzicht!$D$7),"Referentie",IF(E29="","Geen SW-cijfer",IF(E29>=Overzicht!$D$5,"Prioriteit",IF(E29>=Overzicht!$D$6,"Monitoren","Onder drempel")))) -> Geen SW-cijfer | K29: Bronstore van Drune | L29: Zoekopdracht/Tranco | M29: 46292 | N29: 46292 | O29: nee | P29: <25K / geen SW-data. geen data; bronstore van Drune
A30: DE | B30: Kiezstudio | C30: kiezstudio.com | D30: Mode D&H | F30: =IF(AND(H30<>"",H30<Overzicht!$D$7),"Referentie",IF(E30="","Geen SW-cijfer",IF(E30>=Overzicht!$D$5,"Prioriteit",IF(E30>=Overzicht!$D$6,"Monitoren","Onder drempel")))) -> Geen SW-cijfer | L30: Zoekopdracht/Tranco | M30: 46292 | N30: 46292 | O30: nee | P30: <25K / geen SW-data. geen data
A31: DE | B31: Leipzigmodehausshop | C31: leipzigmodehausshop.de | D31: Mode D&H | F31: =IF(AND(H31<>"",H31<Overzicht!$D$7),"Referentie",IF(E31="","Geen SW-cijfer",IF(E31>=Overzicht!$D$5,"Prioriteit",IF(E31>=Overzicht!$D$6,"Monitoren","Onder drempel")))) -> Geen SW-cijfer | K31: Devjour-netwerk (Althaus/FabrikStil/Leipzig/Schlossberg) | L31: Zoekopdracht/Tranco | M31: 46292 | N31: 46292 | O31: nee | P31: <25K / geen SW-data. geen data
A32: DE | B32: Mathilde Munchen | C32: mathilde-munchen.de | D32: Mode D&H | F32: =IF(AND(H32<>"",H32<Overzicht!$D$7),"Referentie",IF(E32="","Geen SW-cijfer",IF(E32>=Overzicht!$D$5,"Prioriteit",IF(E32>=Overzicht!$D$6,"Monitoren","Onder drempel")))) -> Geen SW-cijfer | J32: PT 64%, DE 36% | L32: Zoekopdracht/Tranco | M32: 46292 | N32: 46292 | O32: nee | P32: <25K / geen SW-data. geen totaal
A33: DE | B33: Modehaushartmann | C33: modehaushartmann.de | D33: Mode D&H | F33: =IF(AND(H33<>"",H33<Overzicht!$D$7),"Referentie",IF(E33="","Geen SW-cijfer",IF(E33>=Overzicht!$D$5,"Prioriteit",IF(E33>=Overzicht!$D$6,"Monitoren","Onder drempel")))) -> Geen SW-cijfer | J33: DE 98% | L33: Zoekopdracht/Tranco | M33: 46292 | N33: 46292 | O33: nee | P33: <25K / geen SW-data. geen totaal (92% paid)
A34: DE | B34: Modemuller | C34: modemuller.de | D34: Mode D&H | F34: =IF(AND(H34<>"",H34<Overzicht!$D$7),"Referentie",IF(E34="","Geen SW-cijfer",IF(E34>=Overzicht!$D$5,"Prioriteit",IF(E34>=Overzicht!$D$6,"Monitoren","Onder drempel")))) -> Geen SW-cijfer | L34: Zoekopdracht/Tranco | M34: 46292 | N34: 46292 | O34: nee | P34: <25K / geen SW-data. geen data
A35: DE | B35: Nina Nicole | C35: nina-nicole.de | D35: Mode D&H | F35: =IF(AND(H35<>"",H35<Overzicht!$D$7),"Referentie",IF(E35="","Geen SW-cijfer",IF(E35>=Overzicht!$D$5,"Prioriteit",IF(E35>=Overzicht!$D$6,"Monitoren","Onder drempel")))) -> Geen SW-cijfer | K35: Nicole (nina-nicole.de / nicole-modehaus.de) | L35: Zoekopdracht/Tranco | M35: 46292 | N35: 46292 | O35: nee | P35: <25K / geen SW-data. geen data; zusterstore van nicole-modehaus.de
A36: DE | B36: Nordmodehaus | C36: nordmodehaus.com | D36: Mode D&H | F36: =IF(AND(H36<>"",H36<Overzicht!$D$7),"Referentie",IF(E36="","Geen SW-cijfer",IF(E36>=Overzicht!$D$5,"Prioriteit",IF(E36>=Overzicht!$D$6,"Monitoren","Onder drempel")))) -> Geen SW-cijfer | J36: DE 97% | L36: Zoekopdracht/Tranco | M36: 46292 | N36: 46292 | O36: nee | P36: <25K / geen SW-data. geen totaal (+255%, 96% paid) → volgende maand checken
A37: DE | B37: Orthoday | C37: orthoday.de | D37: Mode D&H | F37: =IF(AND(H37<>"",H37<Overzicht!$D$7),"Referentie",IF(E37="","Geen SW-cijfer",IF(E37>=Overzicht!$D$5,"Prioriteit",IF(E37>=Overzicht!$D$6,"Monitoren","Onder drempel")))) -> Geen SW-cijfer | L37: Zoekopdracht/Tranco | M37: 46292 | N37: 46292 | O37: nee | P37: <25K / geen SW-data. geen totaal
A38: DE | B38: Sophia Zurich | C38: sophia-zurich.com | D38: Mode D&H | F38: =IF(AND(H38<>"",H38<Overzicht!$D$7),"Referentie",IF(E38="","Geen SW-cijfer",IF(E38>=Overzicht!$D$5,"Prioriteit",IF(E38>=Overzicht!$D$6,"Monitoren","Onder drempel")))) -> Geen SW-cijfer | J38: CH 70%, DE 30% | L38: Zoekopdracht/Tranco | M38: 46292 | N38: 46292 | O38: nee | P38: <25K / geen SW-data. geen totaal (CH)
A39: DE | B39: Stefanberlin | C39: stefanberlin.com | D39: Mode D&H | F39: =IF(AND(H39<>"",H39<Overzicht!$D$7),"Referentie",IF(E39="","Geen SW-cijfer",IF(E39>=Overzicht!$D$5,"Prioriteit",IF(E39>=Overzicht!$D$6,"Monitoren","Onder drempel")))) -> Geen SW-cijfer | J39: DE 100% | L39: Zoekopdracht/Tranco | M39: 46292 | N39: 46292 | O39: nee | P39: <25K / geen SW-data. geen totaal (+338%)
A40: DE | B40: Wittenwald | C40: wittenwald.de | D40: Mode D&H | F40: =IF(AND(H40<>"",H40<Overzicht!$D$7),"Referentie",IF(E40="","Geen SW-cijfer",IF(E40>=Overzicht!$D$5,"Prioriteit",IF(E40>=Overzicht!$D$6,"Monitoren","Onder drempel")))) -> Geen SW-cijfer | J40: ES 55%, AT 30%, DE 15% | L40: Zoekopdracht/Tranco | M40: 46292 | N40: 46292 | O40: nee | P40: <25K / geen SW-data. geen totaal (groei +125%, vooral ES/AT)

Sheet FR
A1: FR
A2: Frankrijk · 15 stores
A4: Land | B4: Store | C4: Website | D4: Categorie | E4: Bezoekers / mnd | F4: Status | G4: Trend vorige mnd | H4: Match-score (1-5) | I4: Paid search | J4: Top landen | K4: Netwerk / operator | L4: Gevonden via | M4: Eerst gevonden | N4: Laatst gecheckt | O4: Producten gekopieerd | P4: Notities
A5: FR | B5: Moreau Lyon | C5: moreau-lyon.fr | D5: Dames & heren | E5: 426400 | F5: =IF(AND(H5<>"",H5<Overzicht!$D$7),"Referentie",IF(E5="","Geen SW-cijfer",IF(E5>=Overzicht!$D$5,"Prioriteit",IF(E5>=Overzicht!$D$6,"Monitoren","Onder drempel")))) -> Prioriteit | G5: 0.3 | H5: 5 | I5: 0.69 | J5: FR 98% | L5: Tranco-scan | M5: 46292 | N5: 46292 | O5: nee | P5: Sleek-thema, 100% ,95, 'MERK | PRODUCT'-titels
A6: FR | B6: Lumière Boutique | C6: lumiereboutique.fr | D6: Dames | E6: 275400 | F6: =IF(AND(H6<>"",H6<Overzicht!$D$7),"Referentie",IF(E6="","Geen SW-cijfer",IF(E6>=Overzicht!$D$5,"Prioriteit",IF(E6>=Overzicht!$D$6,"Monitoren","Onder drempel")))) -> Prioriteit | G6: 0.77 | H6: 5 | I6: 0.79 | J6: FR 100% | L6: Tranco-scan | M6: 46292 | N6: 46292 | O6: nee | P6: Thema 'nieuw thema' → vermoedelijk NL-operator
A7: FR | B7: Laurent Monaco | C7: laurentmonaco.fr | D7: Heren | E7: 268600 | F7: =IF(AND(H7<>"",H7<Overzicht!$D$7),"Referentie",IF(E7="","Geen SW-cijfer",IF(E7>=Overzicht!$D$5,"Prioriteit",IF(E7>=Overzicht!$D$6,"Monitoren","Onder drempel")))) -> Prioriteit | G7: -0.04 | H7: 5 | I7: 0.79 | J7: FR 100% | K7: "Autumn Edit LP"-operator (Laurent Monaco / Wentworth London) | L7: Tranco-scan | M7: 46292 | N7: 46292 | O7: nee | P7: Zelfde thema als Wentworth London (UK) → zelfde operator
A8: FR | B8: Look de Paris | C8: lookdeparis.com | D8: Dames | E8: 235800 | F8: =IF(AND(H8<>"",H8<Overzicht!$D$7),"Referentie",IF(E8="","Geen SW-cijfer",IF(E8>=Overzicht!$D$5,"Prioriteit",IF(E8>=Overzicht!$D$6,"Monitoren","Onder drempel")))) -> Prioriteit | G8: 0.49 | H8: 4 | I8: 0.93 | J8: FR 100% | K8: Look de Paris / Boutique Paris | L8: Tranco-scan | M8: 46292 | N8: 46292 | O8: nee | P8: Identieke catalogus als boutique-paris.fr (165.6K) → netwerk; prijzen op ,99
A9: FR | B9: Armand et Fils | C9: armandetfils.fr | D9: Heren | E9: 195100 | F9: =IF(AND(H9<>"",H9<Overzicht!$D$7),"Referentie",IF(E9="","Geen SW-cijfer",IF(E9>=Overzicht!$D$5,"Prioriteit",IF(E9>=Overzicht!$D$6,"Monitoren","Onder drempel")))) -> Prioriteit | G9: 1.42 | H9: 5 | I9: 0.84 | J9: FR 99% | L9: Tranco-scan | M9: 46292 | N9: 46292 | O9: nee | P9: Sterk groeiend
A10: FR | B10: Boutique Paris | C10: boutique-paris.fr | D10: Dames | E10: 165600 | F10: =IF(AND(H10<>"",H10<Overzicht!$D$7),"Referentie",IF(E10="","Geen SW-cijfer",IF(E10>=Overzicht!$D$5,"Prioriteit",IF(E10>=Overzicht!$D$6,"Monitoren","Onder drempel")))) -> Prioriteit | G10: 0.7 | H10: 4 | I10: 0.38 | J10: FR 100% | K10: Look de Paris / Boutique Paris | L10: Zoekopdracht + Tranco | M10: 46292 | N10: 46292 | O10: nee | P10: Zusterstore Look de Paris
A11: FR | B11: Cette Saison | C11: cettesaison.fr | D11: Dames | E11: 151900 | F11: =IF(AND(H11<>"",H11<Overzicht!$D$7),"Referentie",IF(E11="","Geen SW-cijfer",IF(E11>=Overzicht!$D$5,"Prioriteit",IF(E11>=Overzicht!$D$6,"Monitoren","Onder drempel")))) -> Referentie | G11: 0.61 | H11: 2 | I11: 0.21 | J11: FR 85%, BE 15% | L11: Tranco-scan | M11: 46292 | N11: 46292 | O11: nee | P11: REFERENTIE - ander model. Chinese operator (themanaam), ,99-prijzen - ander model
A12: FR | B12: Maison Villard | C12: maisonvillard.fr | D12: Dames | E12: 95600 | F12: =IF(AND(H12<>"",H12<Overzicht!$D$7),"Referentie",IF(E12="","Geen SW-cijfer",IF(E12>=Overzicht!$D$5,"Prioriteit",IF(E12>=Overzicht!$D$6,"Monitoren","Onder drempel")))) -> Prioriteit | G12: -0.55 | H12: 5 | I12: 0.45 | J12: FR 79%, BE 21% | L12: Tranco-scan | M12: 46292 | N12: 46292 | O12: nee
A13: FR | B13: Parisane | C13: parisane.fr | D13: Heren | E13: 77300 | F13: =IF(AND(H13<>"",H13<Overzicht!$D$7),"Referentie",IF(E13="","Geen SW-cijfer",IF(E13>=Overzicht!$D$5,"Prioriteit",IF(E13>=Overzicht!$D$6,"Monitoren","Onder drempel")))) -> Prioriteit | G13: 0.84 | H13: 5 | I13: 0.69 | J13: FR 100% | L13: Tranco-scan | M13: 46292 | N13: 46292 | O13: nee
A14: FR | B14: Dolce Paris | C14: dolce-paris.com | D14: Dames & heren | E14: 64600 | F14: =IF(AND(H14<>"",H14<Overzicht!$D$7),"Referentie",IF(E14="","Geen SW-cijfer",IF(E14>=Overzicht!$D$5,"Prioriteit",IF(E14>=Overzicht!$D$6,"Monitoren","Onder drempel")))) -> Monitoren | G14: -0.08 | H14: 5 | I14: 0.92 | J14: FR 83% | L14: Tranco-scan | M14: 46292 | N14: 46292 | O14: nee
A15: FR | B15: Laurence Boutique | C15: laurence-boutique.fr | D15: Dames | E15: 63300 | F15: =IF(AND(H15<>"",H15<Overzicht!$D$7),"Referentie",IF(E15="","Geen SW-cijfer",IF(E15>=Overzicht!$D$5,"Prioriteit",IF(E15>=Overzicht!$D$6,"Monitoren","Onder drempel")))) -> Monitoren | G15: -0.5 | H15: 5 | I15: 0.84 | J15: FR 100% | L15: Tranco-scan | M15: 46292 | N15: 46292 | O15: nee
A16: FR | B16: Jetta | C16: jetta.fr | D16: Gemengd | E16: 50900 | F16: =IF(AND(H16<>"",H16<Overzicht!$D$7),"Referentie",IF(E16="","Geen SW-cijfer",IF(E16>=Overzicht!$D$5,"Prioriteit",IF(E16>=Overzicht!$D$6,"Monitoren","Onder drempel")))) -> Monitoren | G16: 0.03 | H16: 3 | I16: 0.05 | J16: FR 100% | L16: Tranco-scan | M16: 46292 | N16: 46292 | O16: nee
A17: FR | B17: Boutique Élégance Bordeaux | C17: boutique-elegance-bordeaux.fr | D17: Dames & heren | E17: 34300 | F17: =IF(AND(H17<>"",H17<Overzicht!$D$7),"Referentie",IF(E17="","Geen SW-cijfer",IF(E17>=Overzicht!$D$5,"Prioriteit",IF(E17>=Overzicht!$D$6,"Monitoren","Onder drempel")))) -> Monitoren | G17: -0.52 | H17: 5 | I17: 0 | J17: FR 100% | L17: Tranco-scan | M17: 46292 | N17: 46292 | O17: nee
A18: FR | B18: Frilivin | C18: frilivin.fr | D18: Heren | E18: 19800 | F18: =IF(AND(H18<>"",H18<Overzicht!$D$7),"Referentie",IF(E18="","Geen SW-cijfer",IF(E18>=Overzicht!$D$5,"Prioriteit",IF(E18>=Overzicht!$D$6,"Monitoren","Onder drempel")))) -> Onder drempel | G18: -0.2 | H18: 4 | I18: 0.29 | J18: FR 93% | L18: Zoekopdracht + Tranco | M18: 46292 | N18: 46292 | O18: nee
A19: FR | B19: Evienne | C19: evienne.fr | D19: Dames | E19: 9100 | F19: =IF(AND(H19<>"",H19<Overzicht!$D$7),"Referentie",IF(E19="","Geen SW-cijfer",IF(E19>=Overzicht!$D$5,"Prioriteit",IF(E19>=Overzicht!$D$6,"Monitoren","Onder drempel")))) -> Onder drempel | G19: -0.62 | H19: 5 | I19: 0.92 | J19: FR 100% | L19: Zoekopdracht | M19: 46292 | N19: 46292 | O19: nee

Sheet UK
A1: UK
A2: Verenigd Koninkrijk · 7 stores
A4: Land | B4: Store | C4: Website | D4: Categorie | E4: Bezoekers / mnd | F4: Status | G4: Trend vorige mnd | H4: Match-score (1-5) | I4: Paid search | J4: Top landen | K4: Netwerk / operator | L4: Gevonden via | M4: Eerst gevonden | N4: Laatst gecheckt | O4: Producten gekopieerd | P4: Notities
A5: UK | B5: Pink Boutique | C5: pinkboutique.co.uk | D5: Dames | E5: 554200 | F5: =IF(AND(H5<>"",H5<Overzicht!$D$7),"Referentie",IF(E5="","Geen SW-cijfer",IF(E5>=Overzicht!$D$5,"Prioriteit",IF(E5>=Overzicht!$D$6,"Monitoren","Onder drempel")))) -> Referentie | G5: -0.24 | H5: 1 | I5: 0.21 | J5: UK 45% | L5: Tranco-scan | M5: 46292 | N5: 46292 | O5: nee | P5: REFERENTIE - ander model. Echt UK-merk (eigen label, £ ,99), GEEN dropship-model - alleen referentie
A6: UK | B6: Wilson & Carter | C6: wilson-and-carter.com | D6: Dames & heren | E6: 200500 | F6: =IF(AND(H6<>"",H6<Overzicht!$D$7),"Referentie",IF(E6="","Geen SW-cijfer",IF(E6>=Overzicht!$D$5,"Prioriteit",IF(E6>=Overzicht!$D$6,"Monitoren","Onder drempel")))) -> Prioriteit | G6: -0.54 | H6: 5 | I6: 0.85 | J6: PH 45%, UK 40% | K6: Wilson & Carter (2 domeinen) | L6: Tranco-scan | M6: 46292 | N6: 46292 | O6: nee | P6: Ook wilsoncarter-london.com (UK 71%). UK-aandeel ≈ 80K; PH-verkeer = waarschijnlijk eigen team/VA's
A7: UK | B7: Wentworth London | C7: wentworthlondon.com | D7: Heren | E7: 86900 | F7: =IF(AND(H7<>"",H7<Overzicht!$D$7),"Referentie",IF(E7="","Geen SW-cijfer",IF(E7>=Overzicht!$D$5,"Prioriteit",IF(E7>=Overzicht!$D$6,"Monitoren","Onder drempel")))) -> Prioriteit | G7: -0.41 | H7: 5 | I7: 0.89 | J7: UK 98% | K7: "Autumn Edit LP"-operator (Laurent Monaco / Wentworth London) | L7: Tranco-scan | M7: 46292 | N7: 46292 | O7: nee | P7: Zelfde operator als Laurent Monaco (FR)
A8: UK | B8: Femme Luxe | C8: femmeluxe.co.uk | D8: Dames | E8: 40800 | F8: =IF(AND(H8<>"",H8<Overzicht!$D$7),"Referentie",IF(E8="","Geen SW-cijfer",IF(E8>=Overzicht!$D$5,"Prioriteit",IF(E8>=Overzicht!$D$6,"Monitoren","Onder drempel")))) -> Referentie | G8: -0.34 | H8: 1 | I8: 0.31 | J8: UK 40% | L8: Tranco-scan | M8: 46292 | N8: 46292 | O8: nee | P8: REFERENTIE - ander model. Eigen merk, geen dropship-model
A9: UK | B9: Chaps London | C9: chapslondon.co.uk | D9: Heren | F9: =IF(AND(H9<>"",H9<Overzicht!$D$7),"Referentie",IF(E9="","Geen SW-cijfer",IF(E9>=Overzicht!$D$5,"Prioriteit",IF(E9>=Overzicht!$D$6,"Monitoren","Onder drempel")))) -> Geen SW-cijfer | G9: 0.93 | H9: 5 | I9: 0.96 | J9: UK 100% | K9: Chaps (chaps-herrenmode.de / chapslondon.co.uk) | L9: Zoekopdracht | M9: 46292 | N9: 46292 | O9: nee | P9: geen SW-cijfer. Zelfde naam als chaps-herrenmode.de → vermoedelijk zelfde operator
A10: UK | B10: London Ward | C10: londonward.co | D10: Heren | F10: =IF(AND(H10<>"",H10<Overzicht!$D$7),"Referentie",IF(E10="","Geen SW-cijfer",IF(E10>=Overzicht!$D$5,"Prioriteit",IF(E10>=Overzicht!$D$6,"Monitoren","Onder drempel")))) -> Geen SW-cijfer | G10: -0.03 | H10: 4 | I10: 0.95 | J10: UK 99% | L10: Zoekopdracht | M10: 46292 | N10: 46292 | O10: nee | P10: geen SW-cijfer
A11: UK | B11: Mayfair & Finch | C11: mayfairandfinch.co.uk | D11: Dames | F11: =IF(AND(H11<>"",H11<Overzicht!$D$7),"Referentie",IF(E11="","Geen SW-cijfer",IF(E11>=Overzicht!$D$5,"Prioriteit",IF(E11>=Overzicht!$D$6,"Monitoren","Onder drempel")))) -> Geen SW-cijfer | G11: 1.74 | H11: 5 | I11: 0.94 | J11: UK 99% | L11: Tranco-scan | M11: 46292 | N11: 46292 | O11: nee | P11: geen SW-cijfer. Snel groeiend, volgende maand checken

Sheet Bestsellers
A1: Bestsellers van prioriteit-competitors
A2: Volgorde volgens de store zelf (sort_by=best-selling, over de hele looptijd, dus ook buiten het seizoen).
A4: Land | B4: Store | C4: Rank | D4: Product | E4: Prijs | F4: Categorie | G4: URL | H4: Opgehaald op
A5: DE | B5: drune.de | C5: 1 | D5: Drune | Elegante Seidenbluse Für Damen | E5: 42.99 | F5: stuttgart-mode-nov20241202 | G5: Bekijk | H5: 46292
A6: DE | B6: drune.de | C6: 2 | D6: Drune | Herren Rollkragenpullover aus hochwertigem Material | E6: 40.99 | F6: kaufmann mode20241203 | G6: Bekijk | H6: 46292
A7: DE | B7: drune.de | C7: 3 | D7: Drune - Gepolsterte Jacke für Herren | E7: 100.95 | F7: kaufmann mode20241203 | G7: Bekijk | H7: 46292
A8: DE | B8: drune.de | C8: 4 | D8: Drune | Dehnbare knitterfreie Hemd | E8: 38.99 | F8: holda königsallee20241203 | G8: Bekijk | H8: 46292
A9: DE | B9: drune.de | C9: 5 | D9: Drune | Karim Hoodie Bequemer Kapuzenpullover | E9: 75.95 | F9: holda königsallee20241203 | G9: Bekijk | H9: 46292
A10: DE | B10: drune.de | C10: 6 | D10: Drune | Leder-Cowboy-Stiefel für Damen | E10: 78.75 | F10: holda königsallee20241203 | G10: Bekijk | H10: 46292
A11: DE | B11: drune.de | C11: 7 | D11: Drune | Oliver Winterweste aus Kordsamt | E11: 87.95 | F11: holda königsallee20241203 | G11: Bekijk | H11: 46292
A12: DE | B12: drune.de | C12: 8 | D12: Drune | Gestepptes Cord-Samt-Jacke – Stil & Komfort Für Damen | E12: 96.99 | F12: luxza fashion20241205 | G12: Bekijk | H12: 46292
A13: DE | B13: drune.de | C13: 9 | D13: Damen-Kleid mit schmeichelhaftem Schnitt für Alltag und besondere Anlässe | E13: 98.95 | F13: luxza fashion20241205 | G13: Bekijk | H13: 46292
A14: DE | B14: drune.de | C14: 10 | D14: Drune | Damen Businessanzug - Eleganz für jedes Meeting | E14: 70.99 | F14: luxza fashion20241205 | G14: Bekijk | H14: 46292
A15: DE | B15: nordheim-mode.de | C15: 1 | D15: Isla™ - Leichtes Kleid | E15: 39.95 | F15: Cotton Dress | G15: Bekijk | H15: 46292
A16: DE | B16: nordheim-mode.de | C16: 2 | D16: Sophie | Elegantes Blumenkleid für den Sommer | E16: 59.95 | F16: Floral Dresses | G16: Bekijk | H16: 46292
... A113: FR | B113: moreau-lyon.fr | C113: 10 | D113: MOREAU LYON | ROBE MIDI ÉLÉGANTE CHIC POUR FEMMES | E113: 69.95 | F113: Women’s Dresses | G113: Bekijk | H113: 46292
A114: FR | B114: lumiereboutique.fr | C114: 1 | D114: Robe Femme Coton Col V Coupe Fluide Style Décontracté Élégant | E114: 44.95 | G114: Bekijk | H114: 46292
A115: FR | B115: lumiereboutique.fr | C115: 2 | D115: Combinaison Femme Élégante Décolleté V Coupe Fluide Jambes Larges | E115: 49.95 | G115: Bekijk | H115: 46292
A116: FR | B116: lumiereboutique.fr | C116: 3 | D116: Sandales Plates Pour Femmes au Style Estival et Élégant | E116: 49.95 | F116: Sandales | G116: Bekijk | H116: 46292
A117: FR | B117: lumiereboutique.fr | C117: 4 | D117: Robe Femme Coton Lin Boutonnée Manches Volantées Style Estival | E117: 44.95 | G117: Bekijk | H117: 46292
A118: FR | B118: lumiereboutique.fr | C118: 5 | D118: Robe Chemise Midi Femme Lin Coton Boutonnée Élégante | E118: 39.95 | F118: Short Sleeve Mini Dress | G118: Bekijk | H118: 46292
A119: FR | B119: lumiereboutique.fr | C119: 6 | D119: Baskets Orthopédiques Femme – Confort Avancé et Design Moderne | E119: 49.95 | G119: Bekijk | H119: 46292
A120: FR | B120: lumiereboutique.fr | C120: 7 | D120: Robe Femme Longue Bohème Lin Coton Coupe Fluide Élégante | E120: 49.95 | G120: Bekijk | H120: 46292
A121: FR | B121: lumiereboutique.fr | C121: 8 | D121: Robe Femme Coton Lin Boutonnée Manches 3/4 Coupe Ample Élégante | E121: 49.95 | G121: Bekijk | H121: 46292
A122: FR | B122: lumiereboutique.fr | C122: 9 | D122: Robe femme midi sans manches à encolure haute et fente – élégante été | E122: 44.95 | G122: Bekijk | H122: 46292
A123: FR | B123: lumiereboutique.fr | C123: 10 | D123: Pull Femme Chaud en Tricot Waffle | Confort & Douceur | E123: 39.95 | G123: Bekijk | H123: 46292
A124: FR | B124: laurentmonaco.fr | C124: 1 | D124: LAURENT MONACO | MANTEAU DEUX PIECES | E124: 79.95 | F124: Men's Coats | G124: Bekijk | H124: 46292
A125: FR | B125: laurentmonaco.fr | C125: 2 | D125: LAURENT MONACO | CHAUSSURES ERGONOMIQUES ORTHOPÉDIQUES | E125: 59.95 | F125: Men's Shoes | G125: Bekijk | H125: 46292
A126: FR | B126: laurentmonaco.fr | C126: 3 | D126: LAURENT MONACO | PANTALONS POUR HOMMES À COUPE CONFORTABLE | E126: 44.95 | F126: Men's Pants | G126: Bekijk | H126: 46292
A127: FR | B127: laurentmonaco.fr | C127: 4 | D127: LAURENT MONACO | POLO DE LUXE À MANCHES LONGUES | E127: 39.95 | F127: Men's Sweaters | G127: Bekijk | H127: 46292
A128: FR | B128: laurentmonaco.fr | C128: 5 | D128: LAURENT MONACO | MANTEAU D'HIVER | E128: 69.95 | F128: Men's Jackets | G128: Bekijk | H128: 46292
A129: FR | B129: laurentmonaco.fr | C129: 6 | D129: LAURENT MONACO | CHEMISE ARTISANALE | E129: 34.95 | F129: Men's T-shirts | G129: Bekijk | H129: 46292
A130: FR | B130: laurentmonaco.fr | C130: 7 | D130: LAURENT MONACO | PULL EN PUR CACHEMIRE | E130: 54.95 | F130: Men's Sweaters | G130: Bekijk | H130: 46292
A131: FR | B131: laurentmonaco.fr | C131: 8 | D131: LAURENT MONACO | CHEMISE DE LUXE AVEC CAPUCHE | E131: 39.95 | F131: Men's T-shirts | G131: Bekijk | H131: 46292
A132: FR | B132: laurentmonaco.fr | C132: 9 | D132: LAURENT MONACO | BOXER EN COTON BIOLOGIQUE POUR HOMME (lot de 3) | E132: 29.95 | F132: Men's Accessories | G132: Bekijk | H132: 46292
A133: FR | B133: laurentmonaco.fr | C133: 10 | D133: LAURENT MONACO | VESTE POUR HOMME DE LUXE | E133: 59.95 | F133: Men's Jackets | G133: Bekijk | H133: 46292
A134: FR | B134: lookdeparis.com | C134: 1 | D134: Arthur - Veste matelassé homme | E134: 69.99 | F134: Homme Veste | G134: Bekijk | H134: 46292
A135: FR | B135: lookdeparis.com | C135: 2 | D135: Pierre - Homme Pull thermique tricoté | E135: 49.99 | F135: Homme Pull | G135: Bekijk | H135: 46292
... A191: UK | B191: chapslondon.co.uk | C191: 10 | D191: Knitted Sweater - Patchwork - Loose Fit - Pullover Sweater - Men's Knitted Jumper | E191: 28.5 | F191: Men's Long Sleeves | G191: Bekijk | H191: 46292

Sheet Legenda
A1: Legenda
A3: Status | B3: Wordt automatisch berekend uit bezoekers en match-score, met de drempels op het Overzicht.
A4: Prioriteit | B4: Bezoekers ≥ drempel prioriteit: opnemen en bestsellers direct overnemen.
A5: Monitoren | B5: Tussen de twee drempels: opnemen en volgende maand opnieuw checken.
A6: Onder drempel | B6: Minder bezoekers dan de monitor-drempel.
A7: Geen SW-cijfer | B7: SimilarWeb toont geen bezoekersaantal (meestal < ~10K per maand).
A8: Referentie | B8: Match-score onder het minimum: groot, maar ander model (bijv. eigen merk).
A9: Match-score | B9: 1–5: hoe sterk de store op onze stores lijkt (Shopify, prijzen op ,95, lange SEO-titels, breed D&H-assortiment, veel paid search).
A10: Paid search | B10: Aandeel betaald zoekverkeer volgens SimilarWeb; hoog = vooral Google Shopping/Ads.
A11: Trend | B11: Verandering in bezoekers t.o.v. de maand ervoor. Groen = ≥ +25%, rood = ≤ −25%.
A12: Netwerk / operator | B12: Stores die vermoedelijk van dezelfde eigenaar zijn (zelfde thema, catalogus of naam).
A13: Producten gekopieerd | B13: Gele invulcel (nee / ja / deels): zelf bijhouden.
A14: Bron | B14: SimilarWeb-websitepagina's (schatting), Tranco-ranglijst, Shopify /products.json van de stores zelf.
A15: Bijwerken | B15: Vraag Claude: 'stuur de competitor sheet' of 'voeg nieuwe competitors toe voor <land>'.
