Workbook

Sheet Strategy & explanation
A1: Launch File – Davy Koopman
A2: Updated 16-10-2026 · per store a product tab and a '– Links' tab · list ±15-25 per store per day · listers fill in Lister / Status / Comment on the Links tab
A4: How to use (listers) | B4: 1) Open the '– Links' tab of your store. 2) Pick your name under Lister. 3) List the product from the link at the advised price. 4) Set Status: Live (published), Draft (prepared, not yet live), Duplicate (already in store) or Issues + a Comment. Work from top to bottom (list order). Always reach your daily target: skip duplicates and list the next one.
A5: Sources (import links) | B5: Only 19 competitors with a verified SimilarWeb figure of ≥75K visits/month, the same dropshipping model and no own label. Smaller or unverified stores only count as confirmation ('also at …, small') and for saturation, never as source.
A6: Source choice per product | B6: Preferably a competitor in a different country than your market (same photo + price at a domestic competitor = direct competition). Then: selling well, best photos, same currency, highest price. '⚠ own market' = only a domestic big source exists: follow the photo advice.
A7: Price | B7: Advised price = price of the source link (take it over; other currency → converted, ending in .95). Never underprice. Below the category sweet spot (P25–P75 of bestsellers) → 'can go higher'.
A8: Photos | B8: Photo score 0-100 (≥6 photos, 1st photo ≥1200 px, portrait 3:4/4:5). Counts in the order; weak photos are removed.
A9: Season & order | B9: Week 1-2 autumn layers, week 3 winter coats/boots (cold markets), week 4 Christmas.
A10: Duplicate check | B10: Products already in your store are removed (photo match). Stores sharing a market (UK) never get the same product.
A12: A · Proven elsewhere, open in your market | B12: Bestseller at big competitor(s) in another country, while no competitor sells it in your market yet. Best chance: proven product without price competition.
A13: B · Broadly proven | B13: Sold by 3+ competitors and a bestseller at a big one. Several strong stores bet on it: low risk.
A14: C · New & rising | B14: Live ≤21 days at a big competitor and already in the top 40% of its ranking. Get in early before it is everywhere.
A15: D · Proven in your market | B15: Bestseller at one competitor in your country (3+ competitors there = skipped). Demand is proven; you compete on ads and photos, not on price.
A16: E · New at a top competitor | B16: Just added (≤14 days) by a store with 150K+ visits. Not yet proven, but these stores test deliberately.
A18: Note | B18: Bestseller rank = position in the store's own 'best selling' sort, not a sales count. Preferably use supplier photos or your own texts rather than copying everything 1:1 from the competitor.
A20: Per store
A21: Stellamea | B21: Market: Spain · EUR · catalogue 491 products (62% women) · 757 products · status: Not listed 366, Draft 0, Live 344, Issues 6, Duplicate 41 Strategy: A 450, B 166, C 78, E 32 Categories: Sweater / hoodie 213, Transition jacket 164, Cardigan 105, Trousers 51, Blazer 49, Boots 44, Blouse / shirt 36, Shoes 36, Set 24, Other 18, Dress 11, Winter coat 6 List weeks: week 1: 596, week 2: 157, week 4: 4 Sources: Lozenda Fashion (315K) 178×, Nordheim Mode (546K) 63×, Harper & Wells Boston (1700K) 48×, Lozenda Fashion (192K) 46×, Leon Boutique (243K) 43×, Leon Boutique (344K) 32×, Nordheim Mode (896K) 30×, Dolce Paris (172K) 26×, Harper & Wells Boston (1500K) 25×, Karlson Berlin (981K) 20×, Vitelli Moda (121K) 18×, Oliver & Blake (199K) 15×, Lumière Boutique (146K) 12×, Lumière Boutique (275K) 10×, Laurent Monaco (269K) 10×, Boutique Paris (166K) 10×, Cole & Harrison (154K) 10×, Look de Paris (236K) 9×, Vitelli Moda (103K) 9×, Laurent Monaco (204K) 8×, Look de Paris (111K) 7×, Alpenkind Mode (118K) 7×, Falkenberg Mode (84K) 6×, Oliver & Blake (98K) 6×, dolce-paris.com (172K) 6×, harperwells-boston.com (1700K) 6×, Wilson & Carter (200K) 5×, Velareeh Haus (134K) 5×, Alpenkind Mode (77K) 4×, North Style Fashion 4×, Davento (own store) · bestseller Davento 4×, nordheim-mode.de (896K) 4×, Velareeh Haus (95K) 3×, Parisane (77K) 3×, Armand et Fils (195K) 3×, Anna Vera 3×, Davies & Cooper 3×, lozendafashion.com (314K) · look-alike 3×, Montarello (206K) 3×, Manchester Boutique 2×, lookdeparis.com (111K) · look-alike 2×, dolce-paris.com (172K) · look-alike 2×, northstyle-fashion.com · look-alike 2×, urbanase.com · look-alike 2×, wilson-and-carter.com (68K) · look-alike 2×, Mayfair & Finch 2×, Risora (115K) 2×, Wentworth London (87K) 1×, Risora (121K) 1×, Nordspur (89K) 1×, Margaret Robinson 1×, Nicole Modehaus (32K) 1×, Marlovale 1×, Marlow & Quinn (20K) 1×, Rosati Milano (55K) 1×, Michael Claire Vancouver 1×, Curve Bloom Nashville 1×, lozendafashion.com · bestseller Davento 1×, parisane.fr · bestseller Davento 1×, armandetfils.fr · bestseller Davento 1×, nordheim-mode.de · bestseller Niaali 1×, velareehhaus.com · bestseller Niaali 1×, Niaali (own store) · bestseller Niaali 1×, boutique-paris.fr (59K) · look-alike 1×, falkenhof-mode.de · look-alike 1×, mayfairandfinch.co.uk · look-alike 1×, annavera.it · look-alike 1×, harperwells-boston.com (1700K) · look-alike 1×, parisane.fr (66K) · look-alike 1×, velareehhaus.com (134K) · look-alike 1×, larkandclover.com (214K) · look-alike 1×, lookdeparis.com (111K) 1×, lumiereboutique.fr (145K) 1×, Boutique Paris (60K) 1×, Rowan Shoes 1×, Moreau Lyon (290K) 1×, Wilson & Carter (68K) 1×, Boutique Élégance Bordeaux (34K) 1×, Armand et Fils (136K) 1×, Amara Fiore 1×, Lune Mode 1×
A22: Davento | B22: Market: Italy, Germany · EUR · catalogue 945 products (62% women) · 669 products · status: Not listed 289, Draft 0, Live 327, Issues 1, Duplicate 52 Strategy: A 309, B 218, C 93, E 39 Categories: Transition jacket 209, Sweater / hoodie 106, Cardigan 87, Trousers 68, Boots 54, Winter coat 34, Shoes 32, Blouse / shirt 26, Blazer 19, Dress 13, Set 11, Other 10 List weeks: week 1: 378, week 2: 204, week 3: 86, week 4: 1 Sources: Harper & Wells Boston (1700K) 103×, Lozenda Fashion (192K) 65×, Harper & Wells Boston (1500K) 62×, Dolce Paris (172K) 62×, Oliver & Blake (199K) 47×, Cole & Harrison (154K) 32×, Lumière Boutique (146K) 24×, Laurent Monaco (204K) 22×, Boutique Paris (166K) 21×, Lumière Boutique (275K) 19×, Nordspur (89K) 18×, Laurent Monaco (269K) 16×, Look de Paris (111K) 15×, Look de Paris (236K) 14×, Montarello (206K) 14×, Wentworth London (106K) 14×, Wilson & Carter (200K) 12×, Oliver & Blake (98K) 12×, Nordheim Mode (546K) 10×, Parisane (77K) 10×, Alpenkind Mode (77K) 9×, Lozenda Fashion (315K) 6×, Nordheim Mode (896K) 6×, Leon Boutique (344K) 5×, dolce-paris.com (172K) 4×, harperwells-boston.com (1700K) 4×, Karlson Berlin (981K) 3×, Moreau Lyon (426K) 2×, Parisane (66K) 2×, Boutique Élégance Bordeaux (34K) 2×, Chaps London 2×, North Style Fashion 2×, Niaali (own store) · bestseller Niaali 2×, urbanase.com · look-alike 2×, Vitelli Moda (103K) 2×, Armand et Fils (136K) 2×, Wentworth London (87K) 1×, Vitelli Moda (121K) 1×, Armand et Fils (195K) 1×, Risora (121K) 1×, Soof & Clay 1×, Emma Claire Hamptons (54K) 1×, Emily Carter Manchester 1×, Leon Boutique (243K) 1×, Wilson & Carter (68K) 1×, Curve Bloom Nashville 1×, Davies & Cooper 1×, Marlow & Quinn (20K) 1×, Walther Mode (32K) 1×, boutique-paris.fr (59K) · look-alike 1×, marlowandquinn.com (19K) · look-alike 1×, wilson-and-carter.com (68K) · look-alike 1×, larkandclover.com (214K) · look-alike 1×, ana-cortez.com · look-alike 1×, lookdeparis.com (111K) · look-alike 1×, nordheim-mode.de (896K) 1×, lumiereboutique.fr (145K) 1×, Velareeh Haus (134K) 1×
A23: Niaali | B23: Market: Poland, United Kingdom · PLN · catalogue 733 products (63% women) · 629 products · status: Not listed 301, Draft 0, Live 259, Issues 7, Duplicate 62 Strategy: A 323, B 97, C 86, E 97 Categories: Transition jacket 224, Sweater / hoodie 115, Winter coat 84, Boots 76, Cardigan 45, Trousers 40, Set 16, Other 14, Blouse / shirt 5, Dress 4, Blazer 3, Shoes 3 List weeks: week 1: 317, week 2: 156, week 3: 155, week 4: 1 Sources: Lozenda Fashion (315K) 104×, Lozenda Fashion (192K) 83×, Dolce Paris (172K) 43×, Oliver & Blake (199K) 35×, Nordheim Mode (896K) 28×, Leon Boutique (344K) 26×, Nordheim Mode (546K) 23×, Harper & Wells Boston (1500K) 20×, Harper & Wells Boston (1700K) 19×, Boutique Paris (166K) 15×, Nordspur (89K) 15×, Vitelli Moda (103K) 15×, Laurent Monaco (269K) 13×, Leon Boutique (243K) 13×, Lumière Boutique (275K) 12×, Vitelli Moda (121K) 12×, Parisane (77K) 11×, Look de Paris (236K) 11×, Look de Paris (111K) 8×, Lumière Boutique (146K) 7×, Velareeh Haus (95K) 6×, Oliver & Blake (98K) 6×, Falkenberg Mode (84K) 6×, Montarello (206K) 6×, Alpenkind Mode (77K) 5×, Risora (115K) 5×, Laurent Monaco (204K) 5×, Velareeh Haus (134K) 5×, Davento (own store) · bestseller Davento 5×, Karlson Berlin (981K) 4×, North Style Fashion 4×, dolce-paris.com (172K) 4×, nordheim-mode.de (896K) 4×, Moreau Lyon (290K) 3×, harperwells-boston.com (1700K) 3×, Risora (121K) 2×, Wilson & Carter (200K) 2×, Vientovida (85K) 2×, Boutique Élégance Bordeaux (34K) 2×, Parisane (66K) 2×, Alpenkind Mode (118K) 2×, leonboutique.co (343K) · look-alike 2×, annavera.it · look-alike 2×, urbanase.com · look-alike 2×, harperwells-boston.com (1700K) · look-alike 2×, lozendafashion.com (314K) · look-alike 2×, Karlson Berlin (301K) 1×, Armand et Fils (195K) 1×, luzestilo.es · bestseller Davento 1×, karlson-berlin.com (301K) · look-alike 1×, Emma Claire Hamptons (54K) 1×, amara-fiore.com · look-alike 1×, marlowandquinn.com (19K) · look-alike 1×, marlovale.com · look-alike 1×, parisane.fr (66K) · look-alike 1×, velareehhaus.com (134K) · look-alike 1×, larkandclover.com (214K) · look-alike 1×, northstyle-fashion.com · look-alike 1×, ana-cortez.com · look-alike 1×, lozendafashion.com (314K) 1×, lumiereboutique.fr (145K) 1×, Nordspur (50K) 1×, Anna Vera 1×, Falkenhof Mode 1×, Paul's Wardrobe 1×, Amara Fiore 1×, Armand et Fils (136K) 1×, Mercer & Bloom 1×, Falkenberg Mode (54K) 1×
A24: Dujje | B24: Market: United Kingdom · GBP · catalogue 392 products (76% women) · 735 products · status: Not listed 300, Draft 0, Live 367, Issues 6, Duplicate 62 Strategy: A 324, B 208, C 109, E 54 Categories: Transition jacket 218, Sweater / hoodie 182, Cardigan 96, Boots 76, Trousers 37, Winter coat 37, Blazer 20, Set 17, Shoes 17, Other 17, Blouse / shirt 15, Dress 3 List weeks: week 1: 398, week 2: 229, week 3: 106, week 4: 2 Sources: Lozenda Fashion (315K) 204×, Lozenda Fashion (192K) 60×, Nordheim Mode (546K) 59×, Dolce Paris (172K) 44×, Leon Boutique (243K) 38×, Harper & Wells Boston (1700K) 30×, Harper & Wells Boston (1500K) 25×, Leon Boutique (344K) 24×, Nordheim Mode (896K) 17×, Karlson Berlin (981K) 16×, Lumière Boutique (275K) 16×, Boutique Paris (166K) 13×, Lumière Boutique (146K) 13×, Oliver & Blake (199K) 10×, Davento (own store) · bestseller Davento 10×, Vitelli Moda (121K) 9×, Look de Paris (236K) 9×, Oliver & Blake (98K) 9×, Alpenkind Mode (118K) 9×, Look de Paris (111K) 8×, Laurent Monaco (269K) 6×, harperwells-boston.com (1700K) 6×, Montarello (206K) 6×, Velareeh Haus (95K) 5×, Vitelli Moda (103K) 5×, Alpenkind Mode (77K) 4×, dolce-paris.com (172K) 4×, nordheim-mode.de (896K) 4×, Falkenberg Mode (84K) 3×, Parisane (77K) 3×, Nordspur (89K) 3×, Anna Vera 3×, Risora (115K) 3×, dolce-paris.com (172K) · look-alike 3×, Nicole Modehaus (32K) 2×, Cole & Harrison (154K) 2×, Rosati Milano (55K) 2×, Laurent Monaco (204K) 2×, oliverandblake.com (198K) · look-alike 2×, mercerandbloom.com · look-alike 2×, urbanase.com · look-alike 2×, lozendafashion.com (314K) · look-alike 2×, northstyle-fashion.com · look-alike 2×, leonboutique.co (343K) · look-alike 2×, Risora (121K) 1×, Moreau Lyon (426K) 1×, Wilson & Carter (200K) 1×, Armand et Fils (195K) 1×, Michael Claire Vancouver 1×, Karlson Berlin (301K) 1×, Boutique Paris (60K) 1×, Marlow & Quinn (20K) 1×, Falkenhof Mode 1×, Margaret Robinson 1×, Falkenberg Mode (54K) 1×, lozendafashion.com · bestseller Davento 1×, marlowandquinn.com · bestseller Davento 1×, amara-fiore.com · bestseller Davento 1×, parisane.fr · bestseller Davento 1×, serentimoda.com · bestseller Davento 1×, velareehhaus.com · bestseller Niaali 1×, lozendafashion.com · bestseller Niaali 1×, Niaali (own store) · bestseller Niaali 1×, lookdeparis.com (111K) · look-alike 1×, margaret-robinson.com · look-alike 1×, annavera.it · look-alike 1×, harperwells-boston.com (1700K) · look-alike 1×, parisane.fr (66K) · look-alike 1×, velareehhaus.com (134K) · look-alike 1×, larkandclover.com (214K) · look-alike 1×, lookdeparis.com (111K) 1×, lumiereboutique.fr (145K) 1×, Velareeh Haus (134K) 1×, North Style Fashion 1×, Moreau Lyon (290K) 1×, Rowan Shoes 1×, Lune Mode 1×, Emma Claire Hamptons (54K) 1×
A25: Migesi | B25: Market: United Kingdom · GBP · catalogue 605 products (53% women) · 711 products · status: Not listed 365, Draft 0, Live 284, Issues 2, Duplicate 60 Strategy: A 368, B 174, C 87, E 62 Categories: Transition jacket 191, Sweater / hoodie 171, Cardigan 109, Boots 86, Trousers 34, Winter coat 33, Blazer 23, Shoes 17, Blouse / shirt 16, Dress 12, Other 10, Set 9 List weeks: week 1: 372, week 2: 218, week 3: 117, week 4: 4 Sources: Lozenda Fashion (315K) 135×, Lozenda Fashion (192K) 79×, Nordheim Mode (896K) 43×, Oliver & Blake (199K) 41×, Harper & Wells Boston (1700K) 39×, Harper & Wells Boston (1500K) 33×, Leon Boutique (344K) 31×, Dolce Paris (172K) 30×, Nordheim Mode (546K) 27×, Leon Boutique (243K) 25×, Boutique Paris (166K) 19×, Vitelli Moda (121K) 15×, Nordspur (89K) 12×, Karlson Berlin (981K) 12×, Falkenberg Mode (84K) 11×, Lumière Boutique (146K) 11×, Alpenkind Mode (118K) 9×, Montarello (206K) 9×, Vitelli Moda (103K) 9×, Alpenkind Mode (77K) 8×, Oliver & Blake (98K) 8×, Laurent Monaco (269K) 7×, Look de Paris (236K) 7×, Wilson & Carter (200K) 5×, Lumière Boutique (275K) 5×, Parisane (77K) 5×, Laurent Monaco (204K) 5×, North Style Fashion 5×, Risora (121K) 4×, Look de Paris (111K) 4×, Nicole Modehaus (32K) 4×, Velareeh Haus (134K) 4×, Davento (own store) · bestseller Davento 4×, dolce-paris.com (172K) 4×, northstyle-fashion.com · look-alike 3×, harperwells-boston.com (1700K) 3×, nordheim-mode.de (896K) 3×, Velareeh Haus (95K) 2×, Armand et Fils (195K) 2×, Anna Vera 2×, lozendafashion.com (314K) · look-alike 2×, Moreau Lyon (290K) 2×, Karlson Berlin (301K) 2×, Cole & Harrison (154K) 1×, Curve Bloom Nashville 1×, Michael Claire Vancouver 1×, Marlow & Quinn (20K) 1×, marlowandquinn.com · bestseller Davento 1×, nordheim-mode.de · bestseller Niaali 1×, oliverandblake.com (198K) · look-alike 1×, lookdeparis.com (111K) · look-alike 1×, nordheim-mode.de (896K) · look-alike 1×, annavera.it · look-alike 1×, urbanase.com · look-alike 1×, harperwells-boston.com (1700K) · look-alike 1×, parisane.fr (66K) · look-alike 1×, velareehhaus.com (134K) · look-alike 1×, larkandclover.com (214K) · look-alike 1×, Risora (115K) 1×, Margaret Robinson 1×, Parisane (66K) 1×, Armand et Fils (136K) 1×, Urbanase 1×, Amara Fiore 1×
A26: Newmae | B26: Market: United States · USD · catalogue 724 products (63% women) · 723 products · status: Not listed 316, Draft 0, Live 327, Issues 2, Duplicate 78 Strategy: A 348, B 210, C 103, E 47 Categories: Transition jacket 203, Sweater / hoodie 185, Boots 102, Cardigan 85, Winter coat 54, Trousers 24, Set 16, Other 14, Dress 12, Blouse / shirt 10, Blazer 9, Shoes 9 List weeks: week 1: 353, week 2: 213, week 3: 152, week 4: 5 Sources: Lozenda Fashion (315K) 216×, Lozenda Fashion (192K) 67×, Nordheim Mode (546K) 57×, Leon Boutique (243K) 41×, Dolce Paris (172K) 38×, Leon Boutique (344K) 34×, Nordheim Mode (896K) 31×, Cole & Harrison (154K) 19×, Karlson Berlin (981K) 15×, Lumière Boutique (275K) 15×, Lumière Boutique (146K) 15×, Boutique Paris (166K) 13×, Alpenkind Mode (118K) 12×, Laurent Monaco (269K) 9×, Wilson & Carter (200K) 8×, Vitelli Moda (121K) 8×, Velareeh Haus (95K) 7×, Parisane (77K) 6×, Laurent Monaco (204K) 6×, Look de Paris (111K) 6×, Alpenkind Mode (77K) 5×, Oliver & Blake (98K) 5×, Falkenberg Mode (84K) 5×, Nordspur (89K) 5×, Vitelli Moda (103K) 5×, Harper & Wells Boston (1700K) 5×, Oliver & Blake (199K) 5×, dolce-paris.com (172K) 5×, Look de Paris (236K) 4×, nordheim-mode.de (896K) 4×, Risora (121K) 3×, Velareeh Haus (134K) 3×, Davento (own store) · bestseller Davento 3×, Harper & Wells Boston (1500K) 2×, Emily Carter Manchester 2×, Rosati Milano (55K) 2×, Anna Vera 2×, wilson-and-carter.com (68K) · look-alike 2×, lozendafashion.com (314K) · look-alike 2×, lumiereboutique.fr (145K) 2×, lozendafashion.com (314K) 2×, Davies & Cooper 2×, Wilson & Carter (68K) 2×, Moreau Lyon (426K) 1×, Wentworth London (87K) 1×, Armand et Fils (195K) 1×, Parisane (66K) 1×, Manchester Boutique 1×, Vientovida (85K) 1×, Karlson Berlin (301K) 1×, boutique-paris.fr (59K) · look-alike 1×, lookdeparis.com (111K) · look-alike 1×, marlovale.com · look-alike 1×, annavera.it · look-alike 1×, chapslondon.co.uk · look-alike 1×, parisane.fr (66K) · look-alike 1×, ana-cortez.com · look-alike 1×, lookdeparis.com (111K) 1×, Nicole Modehaus (32K) 1×, Soof & Clay 1×, Mayfair & Finch 1×, Boutique Paris (60K) 1×, Boutique Élégance Bordeaux (34K) 1×, Moreau Lyon (290K) 1×, Armand et Fils (136K) 1×, Risora (115K) 1×
A28: Allowed sources
A29: Harper & Wells Boston | B29: US · 1,700,000 visits/month
A30: Drune | B30: DE · 1,500,000 visits/month
A31: Nordheim Mode | B31: DE · 896,300 visits/month
A32: Leon Boutique | B32: DE · 343,500 visits/month
A33: Lozenda Fashion | B33: DE · 314,800 visits/month
A34: Moreau Lyon | B34: FR · 289,800 visits/month
A35: Montarello | B35: US · 206,400 visits/month
A36: Laurent Monaco | B36: FR · 204,400 visits/month
A37: Oliver & Blake | B37: US · 198,900 visits/month
A38: Dolce Paris | B38: FR · 172,500 visits/month
A39: Cole & Harrison | B39: UK · 153,900 visits/month
A40: Lumière Boutique | B40: FR · 145,900 visits/month
... A47: Vitelli Moda | B47: IT · 103,300 visits/month

Sheet Stellamea
A1: Stellamea – 757 products to list (Spain, EUR)
A2: Sorted by list order · sources only big competitors (≥75K visits/month, verified) · status is set on the Links tab
A4: # | B4: Photo | C4: List week | D4: Strategy | E4: Score | F4: Product (source title) | G4: Category | H4: W/M | I4: Why this product | J4: Advised price (EUR) | K4: Category sweet spot (EUR) | L4: Price note | M4: Cost price – fill in (EUR) | N4: Margin % | O4: Source (import link) | P4: Source | Q4: Source country | R4: Photo score | S4: Photos | T4: Photo advice | U4: Other (big) sources | V4: Status (from Links) | W4: Added on
A5: 1 | C5: Week 1 | D5: A · Proven elsewhere, open in your market | E5: 102.1 | F5: Pull rayé à col montant pour femme chaud et moderne | G5: Sweater / hoodie | H5: ? | I5: top 17% bestseller at Lumière Boutique (FR, 275K visits/mo) · also at Karlson Berlin (DE), Lozenda Fashion (DE), Nordheim Mode (DE), Boutique Élégance Bordeaux (FR, small) +3 · no competitor sells it in ES yet → open space · added 2 days ago · season fit 1.0 | J5: 44.95 | K5: 44–60 | L5: take over the source link price | N5: =IF(M5="","",(J5-M5)/J5) | O5: Open | P5: Lumière Boutique (275K) | Q5: FR | R5: 93 | S5: 6 photos, 1st 1264×1264 | T5: Main photo free to use (no competitor in your market) | U5: https://karlson-berlin.com/products/carlotta-oversized-rollkragenpullover-mit-kontraststreifen https://nordheim-mode.de/products/clara-gestreifter-rollkragenpullover https://lozendafashion.com/products/rollkragenpullover-damen-oversized-angenehm-warm | V5: ='Stellamea – Links'!H5 | W5: 2026-10-02
A6: 2 | C6: Week 1 | D6: A · Proven elsewhere, open in your market | E6: 101.3 | F6: Elly™ - Hochkragen Weiches Stricktop | G6: Sweater / hoodie | H6: ? | I6: top 11% bestseller at Nordheim Mode (DE, 546K visits/mo) · also at Leon Boutique (DE), Lozenda Fashion (DE), Parisane (FR), Mayfair & Finch (UK, small) +1 · no competitor sells it in ES yet → open space · added 0 days ago · season fit 1.0 | J6: 39.95 | K6: 44–60 | L6: take over the source link price; below the category sweet spot, can go higher: 54.95 | N6: =IF(M6="","",(J6-M6)/J6) | O6: Open | P6: Nordheim Mode (546K) | Q6: DE | R6: 93 | S6: 8 photos, 1st 1200×1200 | T6: Main photo free to use (no competitor in your market) | U6: https://lozendafashion.com/products/strickpullover-damen-hochkragen-weicher-komfort https://leonboutique.co/products/mia-damen-oversized-strickpullover-mit-hochkragen-und-weitem-schnitt https://parisane.fr/products/pull-oversize-femme-a-col-montant-manches-longues | V6: ='Stellamea – Links'!H6 | W6: 2026-10-02
A7: 3 | C7: Week 1 | D7: A · Proven elsewhere, open in your market | E7: 100.2 | F7: Sevira | Entspannter Komfort-Pullover | G7: Sweater / hoodie | H7: ? | I7: top 2% bestseller at Karlson Berlin (DE, 981K visits/mo) · also at Leon Boutique (DE), Maison Villard (FR), Parisane (FR), Boutique Élégance Bordeaux (FR, small) +2 · no competitor sells it in ES yet → open space · added 15 days ago · season fit 1.0 | J7: 49.95 | K7: 44–60 | L7: take over the source link price | N7: =IF(M7="","",(J7-M7)/J7) | O7: Open | P7: Karlson Berlin (981K) | Q7: DE | R7: 100 | S7: 10 photos, 1st 1773×2364 | T7: Main photo free to use (no competitor in your market) | U7: https://leonboutique.co/products/sophie-damen-oversized-strukturstrick-pullover https://maisonvillard.fr/products/pull-oversize-en-maille-gaufree-pour-femme-col-rond-et-longue-coupe-ample-en-coton https://parisane.fr/products/pull-femme-oversize-en-tricot-gaufre-a-col-rond-et-manches-longues | V7: ='Stellamea – Links'!H7 | W7: 2026-10-02
A8: 4 | C8: Week 1 | D8: B · Broadly proven | E8: 99.9 | F8: Victor - Veste Cuir Élégante Moderne Homme | G8: Transition jacket | H8: M | I8: top 1% bestseller at Look de Paris (FR, 236K visits/mo) · also at Boutique Paris (FR), Drune (DE), Boutique Élégance Bordeaux (FR, small), Vientovida (ES, small) · 1 competitor(s) in ES · added 3 days ago · season fit 1.0 | J8: 69.99 | K8: 55–70 | L8: take over the source link price; note: already a bestseller at 1 competitor(s) in your market | N8: =IF(M8="","",(J8-M8)/J8) | O8: Open | P8: Look de Paris (236K) | Q8: FR | R8: 83 | S8: 5 photos, 1st 1080×1080 | T8: Same main photo as 1 competitor(s) in your market → use photo 2 (or a model photo) as main image | U8: https://drune.de/products/ww-elegant-herbstjacke https://boutique-paris.fr/products/pierre-veste-en-cuir-elegante-et-moderne | V8: ='Stellamea – Links'!H8 | W8: 2026-10-02
A9: 5 | C9: Week 1 | D9: A · Proven elsewhere, open in your market | E9: 99.8 | F9: Annika | Damen Bürojacke Figurbetonter Blazer | G9: Blazer | H9: W | I9: top 1% bestseller at Leon Boutique (DE, 243K visits/mo) · also at Harper & Wells Boston (US), Lozenda Fashion (DE), Parisane (FR), Velareeh Haus (DE) +3 · no competitor sells it in ES yet → open space · added 2 days ago · season fit 1.0 | J9: 35.95 | K9: 50–70 | L9: take over the source link price; below the category sweet spot, can go higher: 59.95 | N9: =IF(M9="","",(J9-M9)/J9) | O9: Open | P9: Leon Boutique (243K) | Q9: DE | R9: 87 | S9: 6 photos, 1st 1024×1024 | T9: Main photo free to use (no competitor in your market) | U9: https://lozendafashion.com/products/blazer-damen-tailliert-fur-die-perfekte-silhouette https://velareehhaus.com/products/annika-figurbetonter-buero-blazer https://parisane.fr/products/blazer-femme-cintre-a-col-crante-un-bouton | V9: ='Stellamea – Links'!H9 | W9: 2026-10-02
A10: 6 | C10: Week 1 | D10: A · Proven elsewhere, open in your market | E10: 99.7 | F10: Annika | Damen Eleganter Oversized Pullover | G10: Sweater / hoodie | H10: ? | I10: top 15% bestseller at Leon Boutique (DE, 243K visits/mo) · also at Boutique Paris (FR), Karlson Berlin (DE), Look de Paris (FR), Lozenda Fashion (DE) +12 · no competitor sells it in ES yet → open space · added 7 days ago · season fit 1.0 | J10: 54.95 | K10: 44–60 | L10: take over the source link price | N10: =IF(M10="","",(J10-M10)/J10) | O10: Open | P10: Leon Boutique (243K) | Q10: DE | R10: 90 | S10: 11 photos, 1st 900×1200 | T10: Main photo free to use (no competitor in your market) | U10: https://karlson-berlin.com/products/jane-oversized-pullover-mit-asymmetrischem-saum https://nordheim-mode.de/products/jane-oversized-pullover https://lozendafashion.com/products/strickpullover-damen-oversized | V10: ='Stellamea – Links'!H10 | W10: 2026-10-02
A11: 7 | C11: Week 1 | D11: A · Proven elsewhere, open in your market | E11: 99.5 | F11: Clara | Damen Oversized-Bomberjacke | G11: Transition jacket | H11: W | I11: top 3% bestseller at Nordheim Mode (DE, 546K visits/mo) · also at Karlson Berlin (DE), Leon Boutique (DE), Lozenda Fashion (DE), Lune Mode (IT, small) · no competitor sells it in ES yet → open space · added 7 days ago · season fit 1.0 | J11: 49.95 | K11: 55–70 | L11: take over the source link price; below the category sweet spot, can go higher: 59.95 | N11: =IF(M11="","",(J11-M11)/J11) | O11: Open | P11: Nordheim Mode (546K) | Q11: DE | R11: 94 | S11: 11 photos, 1st 1010×1200 | T11: Main photo free to use (no competitor in your market) | U11: https://karlson-berlin.com/products/clara-oversized-bomberjacke-mit-rippbuendchen https://lozendafashion.com/products/bomberjacke-damen-oversized-schnitt-rippbundchen https://leonboutique.co/products/elisabeth-damen-oversized-steppjacke-bomberjacke-kontrastnaht-kunstleder | V11: ='Stellamea – Links'!H11 | W11: 2026-10-02
A12: 8 | C12: Week 1 | D12: A · Proven elsewhere, open in your market | E12: 99.1 | F12: Isabella™ - Eleganter Rollkragenpullover | G12: Sweater / hoodie | H12: ? | I12: top 5% bestseller at Nordheim Mode (DE, 546K visits/mo) · also at Boutique Paris (FR), Falkenberg Mode (DE), Karlson Berlin (DE), Leon Boutique (DE) +7 · no competitor sells it in ES yet → open space · added 5 days ago · season fit 1.0 | J12: 49.95 | K12: 44–60 | L12: take over the source link price | N12: =IF(M12="","",(J12-M12)/J12) | O12: Open | P12: Nordheim Mode (546K) | Q12: DE | R12: 85 | S12: 6 photos, 1st 750×1000 | T12: Main photo free to use (no competitor in your market) | U12: https://karlson-berlin.com/products/isabella-rollkragenpullover-mit-ueberschnittenen-schultern https://lozendafashion.com/products/rollkragenpullover-damen-weicher-fall-warme-strickflache https://falkenberg-mode.de/products/isabella-rollkragenpullover-aus-kaschmir | V12: ='Stellamea – Links'!H12 | W12: 2026-10-02
A13: 9 | C13: Week 1 | D13: A · Proven elsewhere, open in your market | E13: 98.7 | F13: Eleganter Komfort-Pullover | G13: Sweater / hoodie | H13: ? | I13: top 1% bestseller at Lozenda Fashion (DE, 192K visits/mo) · also at Boutique Paris (FR), Look de Paris (FR), Nordheim Mode (DE), Velareeh Haus (DE) · no competitor sells it in ES yet → open space · added 8 days ago · season fit 1.0 | J13: 32.95 | K13: 44–60 | L13: take over the source link price; below the category sweet spot, can go higher: 54.95 | N13: =IF(M13="","",(J13-M13)/J13) | O13: Open | P13: Lozenda Fashion (192K) | Q13: DE | R13: 87 | S13: 12 photos, 1st 800×1067 | T13: Main photo free to use (no competitor in your market) | U13: https://nordheim-mode.de/products/grace-stilvoller-pullover https://velareehhaus.com/products/freya-weicher-rundhals-strickpullover https://lookdeparis.com/products/sandrine-pull-elegant-texture-col-zippe | V13: ='Stellamea – Links'!H13 | W13: 2026-10-02
A14: 10 | C14: Week 1 | D14: A · Proven elsewhere, open in your market | E14: 98.7 | F14: LONG SLEEVE POLO FOR MEN | G14: Blouse / shirt | H14: M | I14: top 3% bestseller at Wentworth London (UK, 87K visits/mo) · also at Alpenkind Mode (DE), Falkenberg Mode (DE), Karlson Berlin (DE), Leon Boutique (DE) +8 · no competitor sells it in ES yet → open space · added 13 days ago · season fit 1.0 | J14: 28.95 | K14: 39–52 | L14: source link price (24.95 GBP) converted; below the category sweet spot, can go higher: 39.95 | N14: =IF(M14="","",(J14-M14)/J14) | O14: Open | P14: Wentworth London (87K) | Q14: UK | R14: 90 | S14: 12 photos, 1st 900×1200 | T14: Main photo free to use (no competitor in your market) | U14: https://karlson-berlin.com/products/max-langarm-poloshirt-mit-karo-kontrastkragen https://nordheim-mode.de/products/max-langarm-polohemd https://velareehhaus.com/products/chris-herren-warmes-langarm-poloshirt-fw | V14: ='Stellamea – Links'!H14 | W14: 2026-10-02
A15: 11 | C15: Week 1 | D15: B · Broadly proven | E15: 98.7 | F15: Maximilian | Herren Vintage Biker Quilted Jacket Echtleder Reißverschluss | G15: Transition jacket | H15: ? | I15: top 13% bestseller at Leon Boutique (DE, 243K visits/mo) · also at Karlson Berlin (DE), Lozenda Fashion (DE), Nordheim Mode (DE), Velareeh Haus (DE) +2 · 1 competitor(s) in ES · added 6 days ago · season fit 1.0 | J15: 91.95 | K15: 55–70 | L15: take over the source link price; note: already a bestseller at 1 competitor(s) in your market | N15: =IF(M15="","",(J15-M15)/J15) | O15: Open | P15: Leon Boutique (243K) | Q15: DE | R15: 93 | S15: 7 photos, 1st 1200×1200 | T15: Same main photo as 1 competitor(s) in your market → use photo 2 (or a model photo) as main image | U15: https://karlson-berlin.com/products/hawthorne-vintage-jacke-mit-vier-taschen https://nordheim-mode.de/products/vintage-hawthorne-jacke https://lozendafashion.com/products/vintage-jacke-herren-kurzer-schnitt-vier-taschen | V15: ='Stellamea – Links'!H15 | W15: 2026-10-02
A16: 12 | C16: Week 1 | D16: B · Broadly proven | E16: 98.7 | F16: Juliette - Ensemble blazer élégant femme | G16: Blazer | H16: W | I16: top 6% bestseller at Look de Paris (FR, 236K visits/mo) · also at Boutique Paris (FR), Drune (DE), Lune Mode (IT, small), Vientovida (ES, small) · 1 competitor(s) in ES · added 2 days ago · season fit 1.0 | J16: 59.99 | K16: 50–70 | L16: take over the source link price; note: already a bestseller at 1 competitor(s) in your market | N16: =IF(M16="","",(J16-M16)/J16) | O16: Open | P16: Look de Paris (236K) | Q16: FR | R16: 96 | S16: 6 photos, 1st 1075×1344 | T16: Same main photo as 1 competitor(s) in your market → use photo 2 (or a model photo) as main image | U16: https://drune.de/products/drune-elegantes-blazer-set-o4u8u1 https://boutique-paris.fr/products/lina-ensemble-blazer-femme-elegant | V16: ='Stellamea – Links'!H16 | W16: 2026-10-02
... A142: 138 | C142: Week 1 | D142: A · Proven elsewhere, open in your market | E142: 84.2 | F142: Bridget | Relaxed Open-Front Cardigan | G142: Cardigan | H142: ? | I142: top 24% bestseller at Harper & Wells Boston (US, 1500K visits/mo) · also at Look de Paris (FR), Wilson & Carter (UK) · no competitor sells it in ES yet → open space · season fit 1.0 | J142: 63.95 | K142: 45–45 | L142: source link price (69.95 USD) converted | N142: =IF(M142="","",(J142-M142)/J142) | O142: Open | P142: Harper & Wells Boston (1500K) | Q142: US | R142: 100 | S142: 12 photos, 1st 1350×1800 | T142: Main photo free to use (no competitor in your market) | U142: https://lookdeparis.com/products/priya-gilet-elegant-oversize-maille https://wilson-and-carter.com/products/marceline | V142: ='Stellamea – Links'!H142 | W142: 2026-10-02
A143: 139 | C143: Week 1 | D143: B · Broadly proven | E143: 84.1 | F143: Strickjacke Damen | Floral & Leicht | G143: Cardigan | H143: W | I143: top 32% bestseller at Lozenda Fashion (DE, 192K visits/mo) · also at Boutique Élégance Bordeaux (FR, small), Montana Bella (ES, small), Urbanase (US, small) · 1 competitor(s) in ES · added 0 days ago · season fit 1.0 | J143: 37.95 | K143: 45–45 | L143: take over the source link price; below the category sweet spot, can go higher: 44.95 | N143: =IF(M143="","",(J143-M143)/J143) | O143: Open | P143: Lozenda Fashion (192K) | Q143: DE | R143: 71 | S143: 1 photos, 1st 1200×1600 | T143: Same main photo as a competitor in your market → use a different (supplier) photo as main image | V143: ='Stellamea – Links'!H143 | W143: 2026-10-02
A144: 140 | C144: Week 1 | D144: B · Broadly proven | E144: 84 | F144: Completo da donna con blazer e pantaloni | Perfetto per l'autunno | G144: Blazer | H144: W | I144: top 2% bestseller at Vitelli Moda (IT, 121K visits/mo) · also at Karlson Berlin (DE), Nordheim Mode (DE), Nicole Modehaus (DE, small), Vientovida (ES, small) · 1 competitor(s) in ES · season fit 1.0 | J144: 74.95 | K144: 50–70 | L144: take over the source link price | N144: =IF(M144="","",(J144-M144)/J144) | O144: Open | P144: Vitelli Moda (121K) | Q144: IT | R144: 89 | S144: 12 photos, 1st 1080×1080 | T144: Same main photo as 1 competitor(s) in your market → use photo 2 (or a model photo) as main image | U144: https://karlson-berlin.com/products/lucia-zweiteiler-mit-blazer-und-stoffhose https://nordheim-mode.de/products/lucia-hose | V144: ='Stellamea – Links'!H144 | W144: 2026-10-02
A145: 141 | C145: Week 1 | D145: A · Proven elsewhere, open in your market | E145: 84 | F145: Esme | Nordic Patterned Cardigan | G145: Cardigan | H145: ? | I145: top 11% bestseller at Harper & Wells Boston (US, 1500K visits/mo) · also at Boutique Paris (FR) · no competitor sells it in ES yet → open space · season fit 1.0 | J145: 54.95 | K145: 45–45 | L145: source link price (59.95 USD) converted | N145: =IF(M145="","",(J145-M145)/J145) | O145: Open | P145: Harper & Wells Boston (1500K) | Q145: US | R145: 100 | S145: 12 photos, 1st 1350×1800 | T145: Main photo free to use (no competitor in your market) | U145: https://boutique-paris.fr/products/elodie-gilet-feminin-boheme-col-v | V145: ='Stellamea – Links'!H145 | W145: 2026-10-02
A146: 142 | C146: Week 1 | D146: A · Proven elsewhere, open in your market | E146: 83.9 | F146: Maglione invernale a collo alto in tessuto morbido con dettagli sartoriali | G146: Sweater / hoodie | H146: ? | I146: top 17% bestseller at Vitelli Moda (IT, 121K visits/mo) · also at Armand et Fils (FR), Lozenda Fashion (DE), Oliver & Blake (US) · no competitor sells it in ES yet → open space · season fit 1.0 | J146: 54.95 | K146: 44–60 | L146: take over the source link price | N146: =IF(M146="","",(J146-M146)/J146) | O146: Open | P146: Vitelli Moda (121K) | Q146: IT | R146: 80 | S146: 12 photos, 1st 800×800 | T146: Main photo free to use (no competitor in your market) | U146: https://lozendafashion.com/products/pullover-herren-elegant-warmend https://armandetfils.fr/products/pull-homme-col-montant-classique https://oliverandblake.com/products/montclair-cashmere-sweater | V146: ='Stellamea – Links'!H146 | W146: 2026-10-02
A147: 143 | C147: Week 1 | D147: B · Broadly proven | E147: 83.9 | F147: Sweatshirt Damen | Kapuze & Lange Passform | G147: Sweater / hoodie | H147: W | I147: top 34% bestseller at Lozenda Fashion (DE, 192K visits/mo) · also at Velareeh Haus (DE), Mayfair & Finch (UK, small), Mercer & Bloom (US, small) · no competitor sells it in ES yet → open space · added 8 days ago · season fit 1.0 | J147: 42.95 | K147: 44–60 | L147: take over the source link price; below the category sweet spot, can go higher: 54.95 | N147: =IF(M147="","",(J147-M147)/J147) | O147: Open | P147: Lozenda Fashion (192K) | Q147: DE | R147: 87 | S147: 12 photos, 1st 800×1200 | T147: Main photo free to use (no competitor in your market) | U147: https://velareehhaus.com/products/mathilda-oversize-kapuzen-hoodie | V147: ='Stellamea – Links'!H147 | W147: 2026-10-02
A148: 144 | C148: Week 1 | D148: B · Broadly proven | E148: 83.8 | F148: Colton | Classic Rancher Weste | G148: Transition jacket | H148: ? | I148: top 40% bestseller at Karlson Berlin (DE, 981K visits/mo) · also at Lozenda Fashion (DE), Nordheim Mode (DE) · no competitor sells it in ES yet → open space · added 2 days ago · season fit 1.0 | J148: 59.95 | K148: 55–70 | L148: take over the source link price | N148: =IF(M148="","",(J148-M148)/J148) | O148: Open | P148: Karlson Berlin (981K) | Q148: DE | R148: 83 | S148: 5 photos, 1st 1080×1080 | T148: Main photo free to use (no competitor in your market) | U148: https://nordheim-mode.de/products/arthur https://lozendafashion.com/products/strickweste-herren-vielseitig-fur-jede-jahreszeit | V148: ='Stellamea – Links'!H148 | W148: 2026-10-02
A149: 145 | C149: Week 1 | D149: A · Proven elsewhere, open in your market | E149: 83.7 | F149: Premium Herren Pullover | G149: Sweater / hoodie | H149: M | I149: top 11% bestseller at Lozenda Fashion (DE, 192K visits/mo) · also at Leon Boutique (DE), Nordheim Mode (DE), Velareeh Haus (DE), Nicole Modehaus (DE, small) +1 · no competitor sells it in ES yet → open space · season fit 1.0 | J149: 49.95 | K149: 44–60 | L149: take over the source link price | N149: =IF(M149="","",(J149-M149)/J149) | O149: Open | P149: Lozenda Fashion (192K) | Q149: DE | R149: 80 | S149: 11 photos, 1st 800×800 | T149: Main photo free to use (no competitor in your market) | U149: https://nordheim-mode.de/products/ryan-warm-mohair-jersey-blue https://velareehhaus.com/products/matthias-herren-weicher-mohair-rundhals-pullover-fw https://leonboutique.co/products/matthias-herren-weicher-mohair-rundhals-knit-sweater-pullover | V149: ='Stellamea – Links'!H149 | W149: 2026-10-02
A150: 146 | C150: Week 1 | D150: A · Proven elsewhere, open in your market | E150: 83.5 | F150: Doris | Damen Strickpullover mit Lockerer Passform | G150: Sweater / hoodie | H150: W | I150: top 26% bestseller at Leon Boutique (DE, 243K visits/mo) · also at Boutique Paris (FR), Look de Paris (FR), Lozenda Fashion (DE), Nicole Modehaus (DE, small) +1 · no competitor sells it in ES yet → open space · season fit 1.0 | J150: 47.95 | K150: 44–60 | L150: take over the source link price | N150: =IF(M150="","",(J150-M150)/J150) | O150: Open | P150: Leon Boutique (243K) | Q150: DE | R150: 77 | S150: 5 photos, 1st 900×900 | T150: Main photo free to use (no competitor in your market) | U150: https://lozendafashion.com/products/amia-modischer-strickpullover-fur-damen https://lookdeparis.com/products/odile-pull-maille-femme-1 https://boutique-paris.fr/products/marie-pull-en-maille-elegant-pour-femme | V150: ='Stellamea – Links'!H150 | W150: 2026-10-02
A151: 147 | C151: Week 1 | D151: B · Broadly proven | E151: 83.5 | F151: Rollkragenpullover Damen | Weich & Warm | G151: Sweater / hoodie | H151: W | I151: top 36% bestseller at Lozenda Fashion (DE, 192K visits/mo) · also at Falkenberg Mode (DE), Leon Boutique (DE), Lune Mode (IT, small) · no competitor sells it in ES yet → open space · added 7 days ago · season fit 1.0 | J151: 47.95 | K151: 44–60 | L151: take over the source link price | N151: =IF(M151="","",(J151-M151)/J151) | O151: Open | P151: Lozenda Fashion (192K) | Q151: DE | R151: 85 | S151: 6 photos, 1st 750×1000 | T151: Main photo free to use (no competitor in your market) | U151: https://falkenberg-mode.de/products/noura https://leonboutique.co/products/clara-damen-oversized-rollkragen-knit-sweater-aus-weicher-wollmischung | V151: ='Stellamea – Links'!H151 | W151: 2026-10-02
A152: 148 | C152: Week 1 | D152: A · Proven elsewhere, open in your market | E152: 83.4 | F152: Herren Zweiteiliges Anzug Set mit Sakko und Hose | G152: Blazer | H152: M | I152: top 2% bestseller at Alpenkind Mode (DE, 77K visits/mo) · no competitor sells it in ES yet → open space · added 1 days ago · season fit 1.0 | J152: 54.95 | K152: 50–70 | L152: take over the source link price | N152: =IF(M152="","",(J152-M152)/J152) | O152: Open | P152: Alpenkind Mode (77K) | Q152: DE | R152: 75 | S152: 4 photos, 1st 800×1067 | T152: Main photo free to use (no competitor in your market) | V152: ='Stellamea – Links'!H152 | W152: 2026-10-02
A153: 149 | C153: Week 1 | D153: A · Proven elsewhere, open in your market | E153: 83.3 | F153: Maria - Veste De Printemps Élégante | G153: Transition jacket | H153: ? | I153: top 16% bestseller at Boutique Paris (FR, 166K visits/mo) · also at Parisane (FR), Cecile Lavelle (DE, small) · no competitor sells it in ES yet → open space · added 18 days ago · season fit 1.0 | J153: 49.99 | K153: 55–70 | L153: take over the source link price; below the category sweet spot, can go higher: 59.95 | N153: =IF(M153="","",(J153-M153)/J153) | O153: Open | P153: Boutique Paris (166K) | Q153: FR | R153: 86 | S153: 9 photos, 1st 1001×1001 | T153: Main photo free to use (no competitor in your market) | U153: https://parisane.fr/products/veste-en-laine-femme-surchemise-oversize-a-poches | V153: ='Stellamea – Links'!H153 | W153: 2026-10-02
A154: 150 | C154: Week 1 | D154: A · Proven elsewhere, open in your market | E154: 83.2 | F154: Lilla | Strickjacke im französischen Stil | G154: Cardigan | H154: W | I154: top 19% bestseller at Karlson Berlin (DE, 981K visits/mo) · also at Falkenberg Mode (DE), Lozenda Fashion (DE), Velareeh Haus (DE), Amara Fiore (IT, small) +7 · no competitor sells it in ES yet → open space · season fit 1.0 | J154: 44.95 | K154: 45–45 | L154: take over the source link price | N154: =IF(M154="","",(J154-M154)/J154) | O154: Open | P154: Karlson Berlin (981K) | Q154: DE | R154: 87 | S154: 6 photos, 1st 800×1067 | T154: Main photo free to use (no competitor in your market) | U154: https://lozendafashion.com/products/bequeme-strickjacke https://velareehhaus.com/products/annelie-lockere-feminine-strickjacke-fw https://falkenberg-mode.de/products/elvarine | V154: ='Stellamea – Links'!H154 | W154: 2026-10-02
A155: 151 | C155: Week 1 | D155: A · Proven elsewhere, open in your market | E155: 83.1 | F155: Birgit | Damen Freizeit-Strickjacke mit V-Ausschnitt und Knöpfen | G155: Cardigan | H155: W | I155: top 10% bestseller at Leon Boutique (DE, 243K visits/mo) · also at Lozenda Fashion (DE) · no competitor sells it in ES yet → open space · added 6 days ago · season fit 1.0 | J155: 39.95 | K155: 45–45 | L155: take over the source link price; below the category sweet spot, can go higher: 44.95 | N155: =IF(M155="","",(J155-M155)/J155) | O155: Open | P155: Leon Boutique (243K) | Q155: DE | R155: 80 | S155: 12 photos, 1st 800×799 | T155: Main photo free to use (no competitor in your market) | U155: https://lozendafashion.com/products/strickjacke-damen-v-ausschnitt-mit-knopfleiste | V155: ='Stellamea – Links'!H155 | W155: 2026-10-02
A156: 152 | C156: Week 1 | D156: A · Proven elsewhere, open in your market | E156: 83.1 | F156: Adrian | Casual Modern Button Cardigan | G156: Cardigan | H156: ? | I156: top 4% bestseller at Harper & Wells Boston (US, 1500K visits/mo) · also at Wilson & Carter (UK), Lune Mode (IT, small), Paul's Wardrobe (US, small) · no competitor sells it in ES yet → open space · season fit 1.0 | J156: 73.95 | K156: 45–45 | L156: source link price (79.95 USD) converted | N156: =IF(M156="","",(J156-M156)/J156) | O156: Open | P156: Harper & Wells Boston (1500K) | Q156: US | R156: 87 | S156: 8 photos, 1st 1024×1024 | T156: Main photo free to use (no competitor in your market) | U156: https://wilson-and-carter.com/products/godfrey-cardigan | V156: ='Stellamea – Links'!H156 | W156: 2026-10-02
A157: 153 | C157: Week 1 | D157: A · Proven elsewhere, open in your market | E157: 83.1 | F157: Blazer Set Damen | Business Look mit Komfort | G157: Blazer | H157: W | I157: top 21% bestseller at Lozenda Fashion (DE, 192K visits/mo) · also at Velareeh Haus (DE) · no competitor sells it in ES yet → open space · added 9 days ago · season fit 1.0 | J157: 59.95 | K157: 50–70 | L157: take over the source link price | N157: =IF(M157="","",(J157-M157)/J157) | O157: Open | P157: Lozenda Fashion (192K) | Q157: DE | R157: 100 | S157: 6 photos, 1st 1200×1800 | T157: Main photo free to use (no competitor in your market) | U157: https://velareehhaus.com/products/johanna-stilvolles-blazer-hosen-set | V157: ='Stellamea – Links'!H157 | W157: 2026-10-02
A158: 154 | C158: Week 1 | D158: A · Proven elsewhere, open in your market | E158: 82.8 | F158: Mantel Damen | Lang mit breitem Reverskragen | G158: Transition jacket | H158: W | I158: top 15% bestseller at Lozenda Fashion (DE, 192K visits/mo) · also at Karlson Berlin (DE), North Style Fashion (US, small) · no competitor sells it in ES yet → open space · added 8 days ago · season fit 1.0 | J158: 37.95 | K158: 55–70 | L158: take over the source link price; below the category sweet spot, can go higher: 59.95 | N158: =IF(M158="","",(J158-M158)/J158) | O158: Open | P158: Lozenda Fashion (192K) | Q158: DE | R158: 71 | S158: 4 photos, 1st 2160×3754 | T158: Main photo free to use (no competitor in your market) | U158: https://karlson-berlin.com/products/hertha-langer-mantel-mit-breitem-reverskragen | V158: ='Stellamea – Links'!H158 | W158: 2026-10-02
A159: 155 | C159: Week 1 | D159: B · Broadly proven | E159: 82.5 | F159: Strickpullover Damen | Naturprint & Gemütliche Passform | G159: Sweater / hoodie | H159: W | I159: top 32% bestseller at Lozenda Fashion (DE, 192K visits/mo) · also at Amara Fiore (IT, small), Lune Mode (IT, small), Walther Mode (IT, small) · no competitor sells it in ES yet → open space · added 6 days ago · season fit 1.0 | J159: 46.95 | K159: 44–60 | L159: take over the source link price | N159: =IF(M159="","",(J159-M159)/J159) | O159: Open | P159: Lozenda Fashion (192K) | Q159: DE | R159: 76 | S159: 3 photos, 1st 1440×1440 | T159: Main photo free to use (no competitor in your market) | V159: ='Stellamea – Links'!H159 | W159: 2026-10-02
A160: 156 | C160: Week 1 | D160: B · Broadly proven | E160: 82.5 | F160: Sarah | Elegant & Cozy Cardigan | G160: Cardigan | H160: ? | I160: top 1% bestseller at Harper & Wells Boston (US, 1500K visits/mo) · also at Oliver & Blake (US), Wilson & Carter (UK), Lune Mode (IT, small), Mayfair & Finch (UK, small) +3 · 1 competitor(s) in ES · season fit 1.0 | J160: 54.95 | K160: 45–45 | L160: source link price (59.95 USD) converted | N160: =IF(M160="","",(J160-M160)/J160) | O160: Open | P160: Harper & Wells Boston (1500K) | Q160: US | R160: 87 | S160: 7 photos, 1st 817×1089 | T160: Same main photo as 1 competitor(s) in your market → use photo 2 (or a model photo) as main image | U160: https://wilson-and-carter.com/products/camellia-cardigan https://oliverandblake.com/products/ofelia-elegant-long-cardigan-sweater | V160: ='Stellamea – Links'!H160 | W160: 2026-10-02
A161: 157 | C161: Week 1 | D161: A · Proven elsewhere, open in your market | E161: 82.5 | F161: Amelie | Stylish Velvet-Touch Bohemian Cardigan | G161: Cardigan | H161: ? | I161: top 10% bestseller at Wilson & Carter (UK, 200K visits/mo) · also at Donna's Dresses (US, small), Lune Mode (IT, small), Paul's Wardrobe (US, small), Soof & Clay (IT, small) · no competitor sells it in ES yet → open space · season fit 1.0 | J161: 57.95 | K161: 45–45 | L161: source link price (49.95 GBP) converted | N161: =IF(M161="","",(J161-M161)/J161) | O161: Open | P161: Wilson & Carter (200K) | Q161: UK | R161: 100 | S161: 10 photos, 1st 1728×2304 | T161: Main photo free to use (no competitor in your market) | V161: ='Stellamea – Links'!H161 | W161: 2026-10-02
A162: 158 | C162: Week 1 | D162: B · Broadly proven | E162: 82.2 | F162: Robert | Herren Freizeit-Polo-Sweatshirt mit langen Ärmeln | G162: Sweater / hoodie | H162: M | I162: top 10% bestseller at Leon Boutique (DE, 243K visits/mo) · also at Laurent Monaco (FR), Velareeh Haus (DE), Chaps London (UK, small), Vientovida (ES, small) · 1 competitor(s) in ES · season fit 1.0 | J162: 39.95 | K162: 44–60 | L162: take over the source link price; below the category sweet spot, can go higher: 54.95 | N162: =IF(M162="","",(J162-M162)/J162) | O162: Open | P162: Leon Boutique (243K) | Q162: DE | R162: 77 | S162: 10 photos, 1st 500×666 | T162: Same main photo as 1 competitor(s) in your market → use photo 2 (or a model photo) as main image | U162: https://velareehhaus.com/products/robert-herren-langarm-polo-sweatshirt https://laurentmonaco.fr/products/laurent-monaco-pull-over-polo-decontracte | V162: ='Stellamea – Links'!H162 | W162: 2026-10-02
A163: 159 | C163: Week 1 | D163: A · Proven elsewhere, open in your market | E163: 82.2 | F163: Isla™ - Leichte Zip-Up Jacke | G163: Transition jacket | H163: ? | I163: top 7% bestseller at Nordheim Mode (DE, 546K visits/mo) · also at Boutique Paris (FR), Leon Boutique (DE), Look de Paris (FR), Lozenda Fashion (DE) +1 · no competitor sells it in ES yet → open space · added 8 days ago · season fit 0.8 | J163: 39.95 | K163: 55–70 | L163: take over the source link price; below the category sweet spot, can go higher: 59.95 | N163: =IF(M163="","",(J163-M163)/J163) | O163: Open | P163: Nordheim Mode (546K) | Q163: DE | R163: 100 | S163: 12 photos, 1st 1350×1800 | T163: Main photo free to use (no competitor in your market) | U163: https://lozendafashion.com/products/steppjacke-damen-leicht-taillenkurz-geschnitten https://leonboutique.co/products/annika-damen-steppjacke-leichte-zip-up-bomberjacke-strukturierter-stoff https://lookdeparis.com/products/aurelie-veste-elegante-texturee-zippee | V163: ='Stellamea – Links'!H163 | W163: 2026-10-02
A164: 160 | C164: Week 1 | D164: A · Proven elsewhere, open in your market | E164: 82 | F164: Emilio Striped Blazer | G164: Blazer | H164: ? | I164: top 4% bestseller at Oliver & Blake (US, 98K visits/mo) · also at Parisane (FR) · no competitor sells it in ES yet → open space · season fit 1.0 | J164: 63.95 | K164: 50–70 | L164: source link price (69.99 USD) converted | N164: =IF(M164="","",(J164-M164)/J164) | O164: Open | P164: Oliver & Blake (98K) | Q164: US | R164: 96 | S164: 6 photos, 1st 1086×1448 | T164: Main photo free to use (no competitor in your market) | U164: https://parisane.fr/products/blazer-homme-raye-en-seersucker-leger-a-col-crante-et-coupe-cintree | V164: ='Stellamea – Links'!H164 | W164: 2026-10-02
A165: 161 | C165: Week 1 | D165: A · Proven elsewhere, open in your market | E165: 81.8 | F165: Madison | Chic Striped Silhouette Blouse | G165: Blouse / shirt | H165: ? | I165: top 4% bestseller at Harper & Wells Boston (US, 1500K visits/mo) · also at Lozenda Fashion (DE), Wilson & Carter (UK), Margaret Robinson (US, small), Mercer & Bloom (US, small) +1 · no competitor sells it in ES yet → open space · season fit 1.0 | J165: 45.95 | K165: 39–52 | L165: source link price (49.95 USD) converted | N165: =IF(M165="","",(J165-M165)/J165) | O165: Open | P165: Harper & Wells Boston (1500K) | Q165: US | R165: 82 | S165: 3 photos, 1st 1200×1600 | T165: Main photo free to use (no competitor in your market) | U165: https://lozendafashion.com/products/damen-retro-gestreiftes-lockeres-langarm-top https://wilson-and-carter.com/products/juliet-blouse | V165: ='Stellamea – Links'!H165 | W165: 2026-10-02
A166: 162 | C166: Week 1 | D166: A · Proven elsewhere, open in your market | E166: 81.8 | F166: Blazer cintré pour femme – élégant, confortable et polyvalent | G166: Blazer | H166: ? | I166: top 3% bestseller at Lumière Boutique (FR, 275K visits/mo) · also at Harper & Wells Boston (US), Wilson & Carter (UK), Amara Fiore (IT, small), Dolce Paris (FR, small) +4 · no competitor sells it in ES yet → open space · season fit 1.0 | J166: 39.95 | K166: 50–70 | L166: take over the source link price; below the category sweet spot, can go higher: 59.95 | N166: =IF(M166="","",(J166-M166)/J166) | O166: Open | P166: Lumière Boutique (275K) | Q166: FR | R166: 87 | S166: 8 photos, 1st 1024×1024 | T166: Main photo free to use (no competitor in your market) | U166: https://wilson-and-carter.com/products/charlotte-blazer https://harperwells-boston.com/products/sabine | V166: ='Stellamea – Links'!H166 | W166: 2026-10-02
...

Sheet Stellamea – Links
A1: Stellamea: import links in list order – list 15-25 per day, then set Lister and Status
A3: # | B3: List week | C3: Product Name | D3: Link | E3: Advised price (EUR) | F3: Source | G3: Lister | H3: Status | I3: Comment | J3: Added on
A5: 1 | B5: Week 1 | D5: https://lumiereboutique.fr/products/marivelle | E5: 44.95 | F5: Lumière Boutique (275K) | G5: Davy | H5: Live | J5: 2026-10-02
A6: 2 | B6: Week 1 | D6: https://nordheim-mode.de/products/elly-hochkragen-weiches-stricktop | E6: 39.95 | F6: Nordheim Mode (546K) | G6: Davy | H6: Live | J6: 2026-10-02
A7: 3 | B7: Week 1 | D7: https://karlson-berlin.com/products/sevira | E7: 49.95 | F7: Karlson Berlin (981K) | G7: Davy | H7: Live | J7: 2026-10-02
A8: 4 | B8: Week 1 | D8: https://lookdeparis.com/products/victor-veste-cuir-elegante-moderne-homme | E8: 69.99 | F8: Look de Paris (236K) | G8: Davy | H8: Live | J8: 2026-10-02
A9: 5 | B9: Week 1 | D9: https://leonboutique.co/products/annika-damen-burojacke-figurbetonter-blazer | E9: 35.95 | F9: Leon Boutique (243K) | G9: Davy | H9: Live | J9: 2026-10-02
A10: 6 | B10: Week 1 | D10: https://leonboutique.co/products/annika-damen-eleganter-oversized-pullover | E10: 54.95 | F10: Leon Boutique (243K) | G10: Davy | H10: Live | J10: 2026-10-02
A11: 7 | B11: Week 1 | D11: https://nordheim-mode.de/products/clara-damen-oversized-bomberjacke | E11: 49.95 | F11: Nordheim Mode (546K) | G11: Davy | H11: Duplicate | I11: Already in store | J11: 2026-10-02
A12: 8 | B12: Week 1 | D12: https://nordheim-mode.de/products/isabella-cashmere-rollkragenpullover | E12: 49.95 | F12: Nordheim Mode (546K) | G12: Davy | H12: Live | J12: 2026-10-02
A13: 9 | B13: Week 1 | D13: https://lozendafashion.com/products/eleganter-komfort-pullover | E13: 32.95 | F13: Lozenda Fashion (192K) | G13: Davy | H13: Live | J13: 2026-10-02
A14: 10 | B14: Week 1 | D14: https://wentworthlondon.com/products/long-sleeve-polo-for-men | E14: 28.95 | F14: Wentworth London (87K) | G14: Davy | H14: Live | J14: 2026-10-02
A15: 11 | B15: Week 1 | D15: https://leonboutique.co/products/maximilian-herren-vintage-biker-quilted-jacket-echtleder-reiverschluss | E15: 91.95 | F15: Leon Boutique (243K) | G15: Davy | H15: Live | J15: 2026-10-02
A16: 12 | B16: Week 1 | D16: https://lookdeparis.com/products/juliette-ensemble-blazer-elegant-femme | E16: 59.99 | F16: Look de Paris (236K) | G16: Davy | H16: Duplicate | I16: Already in store | J16: 2026-10-02
A17: 13 | B17: Week 1 | D17: https://harperwells-boston.com/products/margaret-sweatshirt | E17: 45.95 | F17: Harper & Wells Boston (1500K) | G17: Davy | H17: Live | J17: 2026-10-02
A18: 14 | B18: Week 1 | D18: https://karlson-berlin.com/products/wilson | E18: 54.95 | F18: Karlson Berlin (981K) | G18: Davy | H18: Live | J18: 2026-10-02
A19: 15 | B19: Week 1 | D19: https://nordheim-mode.de/products/jade-strickpullover | E19: 39.95 | F19: Nordheim Mode (546K) | G19: Davy | H19: Live | J19: 2026-10-02
A20: 16 | B20: Week 1 | D20: https://nordheim-mode.de/products/leopardenmuster-denim-patchwork-pullover | E20: 54.95 | F20: Nordheim Mode (546K) | G20: Davy | H20: Live | J20: 2026-10-02
A21: 17 | B21: Week 1 | D21: https://leonboutique.co/products/karl-lassiger-herren-hoodie-mit-reissverschluss | E21: 49.95 | F21: Leon Boutique (243K) | G21: Davy | H21: Duplicate | I21: Already in store | J21: 2026-10-02
A22: 18 | B22: Week 1 | D22: https://vitellimoda.com/products/donna-inverno-cardigan-solido-bottoni-maniche-lunghe | E22: 54.95 | F22: Vitelli Moda (121K) | G22: Davy | H22: Live | J22: 2026-10-02
A23: 19 | B23: Week 1 | D23: https://nordheim-mode.de/products/gabriele-jacke | E23: 49.95 | F23: Nordheim Mode (546K) | G23: Davy | H23: Live | J23: 2026-10-02
A24: 20 | B24: Week 1 | D24: https://lozendafashion.com/products/cordjacke-damen-gemutlich-wandelbar | E24: 57.95 | F24: Lozenda Fashion (192K) | G24: Davy | H24: Live | J24: 2026-10-02
A25: 21 | B25: Week 1 | D25: https://karlson-berlin.com/products/harron | E25: 49.95 | F25: Karlson Berlin (981K) | G25: Davy | H25: Live | J25: 2026-10-02
A26: 22 | B26: Week 1 | D26: https://lookdeparis.com/products/chanel-manteau-de-pluie-femme-long | E26: 59.99 | F26: Look de Paris (236K) | G26: Davy | H26: Live | J26: 2026-10-02
A27: 23 | B27: Week 1 | D27: https://falkenberg-mode.de/products/fabiola | E27: 49.95 | F27: Falkenberg Mode (84K) | G27: Davy | H27: Live | J27: 2026-10-02
A28: 24 | B28: Week 1 | D28: https://nordheim-mode.de/products/giuseppina-regenmantel | E28: 49.95 | F28: Nordheim Mode (546K) | G28: Davy | H28: Live | J28: 2026-10-02
A29: 25 | B29: Week 1 | D29: https://lookdeparis.com/products/louise-cardigan-elegant-automne-femme | E29: 59.99 | F29: Look de Paris (236K) | G29: Davy | H29: Live | J29: 2026-10-02
A30: 26 | B30: Week 1 | C30: Jersey de punto para mujer con canesú de estilo nórdico para el otoño | D30: https://leonboutique.co/products/dorothea-damen-strickpullover-mit-rundhalsausschnitt-fur-den-alltag | E30: 44.95 | F30: Leon Boutique (243K) | G30: Fatima | H30: Live | J30: 2026-10-02
A31: 27 | B31: Week 1 | C31: Jersey de punto para mujer con bloques de color y detalle de leopardo | D31: https://leonboutique.co/products/viola-damen-weicher-strickpullover-mit-farbblock-und-leopardenmuster | E31: 52.95 | F31: Leon Boutique (243K) | G31: Fatima | H31: Live | J31: 2026-10-02
A32: 28 | B32: Week 1 | C32: Jersey de punto acanalado para hombre con media cremallera para el otoño | D32: https://laurentmonaco.fr/products/laurent-monaco-pull-tendance-avec-zip-moyen-homme | E32: 44.95 | F32: Laurent Monaco (269K) | G32: Fatima | H32: Live | J32: 2026-10-02
A33: 29 | B33: Week 1 | C33: Chaqueta de punto para hombre con cremallera y dibujo de rombos para el invierno | D33: https://risora-shop.de/products/klassikcardigan-strickjacke-stilvoll-und-bequem | E33: 59.95 | F33: Risora (121K) | G33: Fatima | H33: Live | J33: 2026-10-02
A34: 30 | B34: Week 1 | C34: Blazer para mujer de efecto terciopelo con botones dorados para ocasiones elegantes | D34: https://leonboutique.co/products/sabina-damen-klassischer-blazer-mit-ein-knopf-verschluss | E34: 74.95 | F34: Leon Boutique (243K) | G34: Fatima | H34: Live | J34: 2026-10-02
A35: 31 | B35: Week 1 | C35: Polo de manga larga para hombre con tapeta de tres botones para el otoño | D35: https://karlson-berlin.com/products/orion | E35: 59.95 | F35: Karlson Berlin (981K) | G35: Fatima | H35: Live | J35: 2026-10-02
A36: 32 | B36: Week 1 | C36: Blazer abierto para mujer con mangas fruncidas para el día a día | D36: https://leonboutique.co/products/edith-damen-stilvoller-massgeschneiderter-blazer-fur-freizeitlook | E36: 45.95 | F36: Leon Boutique (243K) | G36: Fatima | H36: Live | J36: 2026-10-02
A37: 33 | B37: Week 1 | C37: Blazer para hombre de efecto ante con cuello mao para el otoño | D37: https://vitellimoda.com/products/blazer-uomo-con-bottoni-a-taglio-strutturato-in-tessuto-premium-ideale-per-lautunno | E37: 67.95 | F37: Vitelli Moda (121K) | G37: Fatima | H37: Live | J37: 2026-10-02
A38: 34 | B38: Week 1 | C38: Jersey para mujer con estampado geométrico 3D para el día a día | D38: https://nordheim-mode.de/products/sanae-trendy-alltags-pullover | E38: 39.95 | F38: Nordheim Mode (546K) | G38: Fatima | H38: Live | J38: 2026-10-02
A39: 35 | B39: Week 1 | C39: Jersey de punto fino para mujer con mangas murciélago para el entretiempo | D39: https://nordheim-mode.de/products/sara-komfortpullover | E39: 34.95 | F39: Nordheim Mode (546K) | G39: Fatima | H39: Live | J39: 2026-10-02
A40: 36 | B40: Week 1 | D40: https://leonboutique.co/products/charlotte-damen-oversized-fledermausarm-strick-sweater | E40: 36.95 | F40: Leon Boutique (243K) | G40: Fatima | H40: Duplicate | I40: Already in store | J40: 2026-10-02
A41: 37 | B41: Week 1 | C41: Jersey de punto para mujer con cuello alto y cordón para el otoño | D41: https://vitellimoda.com/products/maglione-con-collo-alto-in-lana-merino-traspirante-e-termico-versatile-per-occasioni-casual-e-formali | E41: 49.95 | F41: Vitelli Moda (121K) | G41: Fatima | H41: Live | J41: 2026-10-02
A42: 38 | B42: Week 1 | C42: Chaqueta ligera para hombre con forro de cuadros y cremallera para el entretiempo | D42: https://laurentmonaco.fr/products/veste-legere-doublee-a-carreaux-pour-homme | E42: 49.95 | F42: Laurent Monaco (269K) | G42: Fatima | H42: Live | J42: 2026-10-02
...

Sheet Davento
A1: Davento – 669 products to list (Italy/Germany, EUR)
A2: Sorted by list order · sources only big competitors (≥75K visits/month, verified) · status is set on the Links tab
